2022-11-11 16:26:51,120 Not Found: /favicon.ico
2022-11-11 16:36:05,209 Internal Server Error: /
Traceback (most recent call last):
  File "C:\Users\fabro\AppData\Local\Programs\Python\Python310\lib\site-packages\django\template\base.py", line 505, in parse
    compile_func = self.tags[command]
KeyError: 'respone'

During handling of the above exception, another exception occurred:

Traceback (most recent call last):
  File "C:\Users\fabro\AppData\Local\Programs\Python\Python310\lib\site-packages\django\core\handlers\exception.py", line 55, in inner
    response = get_response(request)
  File "C:\Users\fabro\AppData\Local\Programs\Python\Python310\lib\site-packages\django\core\handlers\base.py", line 220, in _get_response
    response = response.render()
  File "C:\Users\fabro\AppData\Local\Programs\Python\Python310\lib\site-packages\django\template\response.py", line 114, in render
    self.content = self.rendered_content
  File "C:\Users\fabro\AppData\Local\Programs\Python\Python310\lib\site-packages\django\template\response.py", line 90, in rendered_content
    template = self.resolve_template(self.template_name)
  File "C:\Users\fabro\AppData\Local\Programs\Python\Python310\lib\site-packages\django\template\response.py", line 72, in resolve_template
    return select_template(template, using=self.using)
  File "C:\Users\fabro\AppData\Local\Programs\Python\Python310\lib\site-packages\django\template\loader.py", line 42, in select_template
    return engine.get_template(template_name)
  File "C:\Users\fabro\AppData\Local\Programs\Python\Python310\lib\site-packages\django\template\backends\django.py", line 34, in get_template
    return Template(self.engine.get_template(template_name), self)
  File "C:\Users\fabro\AppData\Local\Programs\Python\Python310\lib\site-packages\django\template\engine.py", line 175, in get_template
    template, origin = self.find_template(template_name)
  File "C:\Users\fabro\AppData\Local\Programs\Python\Python310\lib\site-packages\django\template\engine.py", line 157, in find_template
    template = loader.get_template(name, skip=skip)
  File "C:\Users\fabro\AppData\Local\Programs\Python\Python310\lib\site-packages\django\template\loaders\cached.py", line 57, in get_template
    template = super().get_template(template_name, skip)
  File "C:\Users\fabro\AppData\Local\Programs\Python\Python310\lib\site-packages\django\template\loaders\base.py", line 28, in get_template
    return Template(
  File "C:\Users\fabro\AppData\Local\Programs\Python\Python310\lib\site-packages\django\template\base.py", line 154, in __init__
    self.nodelist = self.compile_nodelist()
  File "C:\Users\fabro\AppData\Local\Programs\Python\Python310\lib\site-packages\django\template\base.py", line 200, in compile_nodelist
    return parser.parse()
  File "C:\Users\fabro\AppData\Local\Programs\Python\Python310\lib\site-packages\django\template\base.py", line 513, in parse
    raise self.error(token, e)
  File "C:\Users\fabro\AppData\Local\Programs\Python\Python310\lib\site-packages\django\template\base.py", line 511, in parse
    compiled_result = compile_func(self, token)
  File "C:\Users\fabro\AppData\Local\Programs\Python\Python310\lib\site-packages\django\template\loader_tags.py", line 293, in do_extends
    nodelist = parser.parse()
  File "C:\Users\fabro\AppData\Local\Programs\Python\Python310\lib\site-packages\django\template\base.py", line 513, in parse
    raise self.error(token, e)
  File "C:\Users\fabro\AppData\Local\Programs\Python\Python310\lib\site-packages\django\template\base.py", line 511, in parse
    compiled_result = compile_func(self, token)
  File "C:\Users\fabro\AppData\Local\Programs\Python\Python310\lib\site-packages\django\template\loader_tags.py", line 232, in do_block
    nodelist = parser.parse(("endblock",))
  File "C:\Users\fabro\AppData\Local\Programs\Python\Python310\lib\site-packages\django\template\base.py", line 513, in parse
    raise self.error(token, e)
  File "C:\Users\fabro\AppData\Local\Programs\Python\Python310\lib\site-packages\django\template\base.py", line 511, in parse
    compiled_result = compile_func(self, token)
  File "C:\Users\fabro\AppData\Local\Programs\Python\Python310\lib\site-packages\django\template\defaulttags.py", line 854, in do_for
    nodelist_loop = parser.parse(
  File "C:\Users\fabro\AppData\Local\Programs\Python\Python310\lib\site-packages\django\template\base.py", line 507, in parse
    self.invalid_block_tag(token, command, parse_until)
  File "C:\Users\fabro\AppData\Local\Programs\Python\Python310\lib\site-packages\django\template\base.py", line 558, in invalid_block_tag
    raise self.error(
django.template.exceptions.TemplateSyntaxError: Invalid block tag on line 20: 'respone', expected 'empty' or 'endfor'. Did you forget to register or load this tag?
2022-11-11 16:40:34,191 Internal Server Error: /
Traceback (most recent call last):
  File "C:\Users\fabro\AppData\Local\Programs\Python\Python310\lib\site-packages\django\core\handlers\exception.py", line 55, in inner
    response = get_response(request)
  File "C:\Users\fabro\AppData\Local\Programs\Python\Python310\lib\site-packages\django\core\handlers\base.py", line 220, in _get_response
    response = response.render()
  File "C:\Users\fabro\AppData\Local\Programs\Python\Python310\lib\site-packages\django\template\response.py", line 114, in render
    self.content = self.rendered_content
  File "C:\Users\fabro\AppData\Local\Programs\Python\Python310\lib\site-packages\django\template\response.py", line 90, in rendered_content
    template = self.resolve_template(self.template_name)
  File "C:\Users\fabro\AppData\Local\Programs\Python\Python310\lib\site-packages\django\template\response.py", line 72, in resolve_template
    return select_template(template, using=self.using)
  File "C:\Users\fabro\AppData\Local\Programs\Python\Python310\lib\site-packages\django\template\loader.py", line 42, in select_template
    return engine.get_template(template_name)
  File "C:\Users\fabro\AppData\Local\Programs\Python\Python310\lib\site-packages\django\template\backends\django.py", line 34, in get_template
    return Template(self.engine.get_template(template_name), self)
  File "C:\Users\fabro\AppData\Local\Programs\Python\Python310\lib\site-packages\django\template\engine.py", line 175, in get_template
    template, origin = self.find_template(template_name)
  File "C:\Users\fabro\AppData\Local\Programs\Python\Python310\lib\site-packages\django\template\engine.py", line 157, in find_template
    template = loader.get_template(name, skip=skip)
  File "C:\Users\fabro\AppData\Local\Programs\Python\Python310\lib\site-packages\django\template\loaders\cached.py", line 57, in get_template
    template = super().get_template(template_name, skip)
  File "C:\Users\fabro\AppData\Local\Programs\Python\Python310\lib\site-packages\django\template\loaders\base.py", line 28, in get_template
    return Template(
  File "C:\Users\fabro\AppData\Local\Programs\Python\Python310\lib\site-packages\django\template\base.py", line 154, in __init__
    self.nodelist = self.compile_nodelist()
  File "C:\Users\fabro\AppData\Local\Programs\Python\Python310\lib\site-packages\django\template\base.py", line 200, in compile_nodelist
    return parser.parse()
  File "C:\Users\fabro\AppData\Local\Programs\Python\Python310\lib\site-packages\django\template\base.py", line 513, in parse
    raise self.error(token, e)
  File "C:\Users\fabro\AppData\Local\Programs\Python\Python310\lib\site-packages\django\template\base.py", line 511, in parse
    compiled_result = compile_func(self, token)
  File "C:\Users\fabro\AppData\Local\Programs\Python\Python310\lib\site-packages\django\template\loader_tags.py", line 293, in do_extends
    nodelist = parser.parse()
  File "C:\Users\fabro\AppData\Local\Programs\Python\Python310\lib\site-packages\django\template\base.py", line 513, in parse
    raise self.error(token, e)
  File "C:\Users\fabro\AppData\Local\Programs\Python\Python310\lib\site-packages\django\template\base.py", line 511, in parse
    compiled_result = compile_func(self, token)
  File "C:\Users\fabro\AppData\Local\Programs\Python\Python310\lib\site-packages\django\template\loader_tags.py", line 232, in do_block
    nodelist = parser.parse(("endblock",))
  File "C:\Users\fabro\AppData\Local\Programs\Python\Python310\lib\site-packages\django\template\base.py", line 513, in parse
    raise self.error(token, e)
  File "C:\Users\fabro\AppData\Local\Programs\Python\Python310\lib\site-packages\django\template\base.py", line 511, in parse
    compiled_result = compile_func(self, token)
  File "C:\Users\fabro\AppData\Local\Programs\Python\Python310\lib\site-packages\django\template\defaulttags.py", line 854, in do_for
    nodelist_loop = parser.parse(
  File "C:\Users\fabro\AppData\Local\Programs\Python\Python310\lib\site-packages\django\template\base.py", line 513, in parse
    raise self.error(token, e)
  File "C:\Users\fabro\AppData\Local\Programs\Python\Python310\lib\site-packages\django\template\base.py", line 511, in parse
    compiled_result = compile_func(self, token)
  File "C:\Users\fabro\AppData\Local\Programs\Python\Python310\lib\site-packages\django\template\library.py", line 130, in compile_func
    args, kwargs = parse_bits(
  File "C:\Users\fabro\AppData\Local\Programs\Python\Python310\lib\site-packages\django\template\library.py", line 347, in parse_bits
    args.append(parser.compile_filter(bit))
  File "C:\Users\fabro\AppData\Local\Programs\Python\Python310\lib\site-packages\django\template\base.py", line 600, in compile_filter
    return FilterExpression(token, self)
  File "C:\Users\fabro\AppData\Local\Programs\Python\Python310\lib\site-packages\django\template\base.py", line 703, in __init__
    raise TemplateSyntaxError(
django.template.exceptions.TemplateSyntaxError: Could not parse the remainder: '=' from '='
2022-11-11 16:45:00,977 User id 1 responded no to event id 3.
2022-11-11 16:54:06,538 Internal Server Error: /
Traceback (most recent call last):
  File "C:\Users\fabro\AppData\Local\Programs\Python\Python310\lib\site-packages\django\core\handlers\exception.py", line 55, in inner
    response = get_response(request)
  File "C:\Users\fabro\AppData\Local\Programs\Python\Python310\lib\site-packages\django\core\handlers\base.py", line 220, in _get_response
    response = response.render()
  File "C:\Users\fabro\AppData\Local\Programs\Python\Python310\lib\site-packages\django\template\response.py", line 114, in render
    self.content = self.rendered_content
  File "C:\Users\fabro\AppData\Local\Programs\Python\Python310\lib\site-packages\django\template\response.py", line 90, in rendered_content
    template = self.resolve_template(self.template_name)
  File "C:\Users\fabro\AppData\Local\Programs\Python\Python310\lib\site-packages\django\template\response.py", line 72, in resolve_template
    return select_template(template, using=self.using)
  File "C:\Users\fabro\AppData\Local\Programs\Python\Python310\lib\site-packages\django\template\loader.py", line 42, in select_template
    return engine.get_template(template_name)
  File "C:\Users\fabro\AppData\Local\Programs\Python\Python310\lib\site-packages\django\template\backends\django.py", line 34, in get_template
    return Template(self.engine.get_template(template_name), self)
  File "C:\Users\fabro\AppData\Local\Programs\Python\Python310\lib\site-packages\django\template\engine.py", line 175, in get_template
    template, origin = self.find_template(template_name)
  File "C:\Users\fabro\AppData\Local\Programs\Python\Python310\lib\site-packages\django\template\engine.py", line 157, in find_template
    template = loader.get_template(name, skip=skip)
  File "C:\Users\fabro\AppData\Local\Programs\Python\Python310\lib\site-packages\django\template\loaders\cached.py", line 57, in get_template
    template = super().get_template(template_name, skip)
  File "C:\Users\fabro\AppData\Local\Programs\Python\Python310\lib\site-packages\django\template\loaders\base.py", line 28, in get_template
    return Template(
  File "C:\Users\fabro\AppData\Local\Programs\Python\Python310\lib\site-packages\django\template\base.py", line 154, in __init__
    self.nodelist = self.compile_nodelist()
  File "C:\Users\fabro\AppData\Local\Programs\Python\Python310\lib\site-packages\django\template\base.py", line 200, in compile_nodelist
    return parser.parse()
  File "C:\Users\fabro\AppData\Local\Programs\Python\Python310\lib\site-packages\django\template\base.py", line 513, in parse
    raise self.error(token, e)
  File "C:\Users\fabro\AppData\Local\Programs\Python\Python310\lib\site-packages\django\template\base.py", line 511, in parse
    compiled_result = compile_func(self, token)
  File "C:\Users\fabro\AppData\Local\Programs\Python\Python310\lib\site-packages\django\template\loader_tags.py", line 293, in do_extends
    nodelist = parser.parse()
  File "C:\Users\fabro\AppData\Local\Programs\Python\Python310\lib\site-packages\django\template\base.py", line 513, in parse
    raise self.error(token, e)
  File "C:\Users\fabro\AppData\Local\Programs\Python\Python310\lib\site-packages\django\template\base.py", line 511, in parse
    compiled_result = compile_func(self, token)
  File "C:\Users\fabro\AppData\Local\Programs\Python\Python310\lib\site-packages\django\template\loader_tags.py", line 232, in do_block
    nodelist = parser.parse(("endblock",))
  File "C:\Users\fabro\AppData\Local\Programs\Python\Python310\lib\site-packages\django\template\base.py", line 513, in parse
    raise self.error(token, e)
  File "C:\Users\fabro\AppData\Local\Programs\Python\Python310\lib\site-packages\django\template\base.py", line 511, in parse
    compiled_result = compile_func(self, token)
  File "C:\Users\fabro\AppData\Local\Programs\Python\Python310\lib\site-packages\django\template\defaulttags.py", line 854, in do_for
    nodelist_loop = parser.parse(
  File "C:\Users\fabro\AppData\Local\Programs\Python\Python310\lib\site-packages\django\template\base.py", line 513, in parse
    raise self.error(token, e)
  File "C:\Users\fabro\AppData\Local\Programs\Python\Python310\lib\site-packages\django\template\base.py", line 511, in parse
    compiled_result = compile_func(self, token)
  File "C:\Users\fabro\AppData\Local\Programs\Python\Python310\lib\site-packages\django\template\defaulttags.py", line 953, in do_if
    condition = TemplateIfParser(parser, bits).parse()
  File "C:\Users\fabro\AppData\Local\Programs\Python\Python310\lib\site-packages\django\template\smartif.py", line 197, in parse
    raise self.error_class(
django.template.exceptions.TemplateSyntaxError: Unused 'events.id' at end of if expression.
2022-11-11 17:27:11,163 Internal Server Error: /
Traceback (most recent call last):
  File "C:\Users\fabro\AppData\Local\Programs\Python\Python310\lib\site-packages\django\template\base.py", line 505, in parse
    compile_func = self.tags[command]
KeyError: 'respone'

During handling of the above exception, another exception occurred:

Traceback (most recent call last):
  File "C:\Users\fabro\AppData\Local\Programs\Python\Python310\lib\site-packages\django\core\handlers\exception.py", line 55, in inner
    response = get_response(request)
  File "C:\Users\fabro\AppData\Local\Programs\Python\Python310\lib\site-packages\django\core\handlers\base.py", line 220, in _get_response
    response = response.render()
  File "C:\Users\fabro\AppData\Local\Programs\Python\Python310\lib\site-packages\django\template\response.py", line 114, in render
    self.content = self.rendered_content
  File "C:\Users\fabro\AppData\Local\Programs\Python\Python310\lib\site-packages\django\template\response.py", line 90, in rendered_content
    template = self.resolve_template(self.template_name)
  File "C:\Users\fabro\AppData\Local\Programs\Python\Python310\lib\site-packages\django\template\response.py", line 72, in resolve_template
    return select_template(template, using=self.using)
  File "C:\Users\fabro\AppData\Local\Programs\Python\Python310\lib\site-packages\django\template\loader.py", line 42, in select_template
    return engine.get_template(template_name)
  File "C:\Users\fabro\AppData\Local\Programs\Python\Python310\lib\site-packages\django\template\backends\django.py", line 34, in get_template
    return Template(self.engine.get_template(template_name), self)
  File "C:\Users\fabro\AppData\Local\Programs\Python\Python310\lib\site-packages\django\template\engine.py", line 175, in get_template
    template, origin = self.find_template(template_name)
  File "C:\Users\fabro\AppData\Local\Programs\Python\Python310\lib\site-packages\django\template\engine.py", line 157, in find_template
    template = loader.get_template(name, skip=skip)
  File "C:\Users\fabro\AppData\Local\Programs\Python\Python310\lib\site-packages\django\template\loaders\cached.py", line 57, in get_template
    template = super().get_template(template_name, skip)
  File "C:\Users\fabro\AppData\Local\Programs\Python\Python310\lib\site-packages\django\template\loaders\base.py", line 28, in get_template
    return Template(
  File "C:\Users\fabro\AppData\Local\Programs\Python\Python310\lib\site-packages\django\template\base.py", line 154, in __init__
    self.nodelist = self.compile_nodelist()
  File "C:\Users\fabro\AppData\Local\Programs\Python\Python310\lib\site-packages\django\template\base.py", line 200, in compile_nodelist
    return parser.parse()
  File "C:\Users\fabro\AppData\Local\Programs\Python\Python310\lib\site-packages\django\template\base.py", line 513, in parse
    raise self.error(token, e)
  File "C:\Users\fabro\AppData\Local\Programs\Python\Python310\lib\site-packages\django\template\base.py", line 511, in parse
    compiled_result = compile_func(self, token)
  File "C:\Users\fabro\AppData\Local\Programs\Python\Python310\lib\site-packages\django\template\loader_tags.py", line 293, in do_extends
    nodelist = parser.parse()
  File "C:\Users\fabro\AppData\Local\Programs\Python\Python310\lib\site-packages\django\template\base.py", line 513, in parse
    raise self.error(token, e)
  File "C:\Users\fabro\AppData\Local\Programs\Python\Python310\lib\site-packages\django\template\base.py", line 511, in parse
    compiled_result = compile_func(self, token)
  File "C:\Users\fabro\AppData\Local\Programs\Python\Python310\lib\site-packages\django\template\loader_tags.py", line 232, in do_block
    nodelist = parser.parse(("endblock",))
  File "C:\Users\fabro\AppData\Local\Programs\Python\Python310\lib\site-packages\django\template\base.py", line 513, in parse
    raise self.error(token, e)
  File "C:\Users\fabro\AppData\Local\Programs\Python\Python310\lib\site-packages\django\template\base.py", line 511, in parse
    compiled_result = compile_func(self, token)
  File "C:\Users\fabro\AppData\Local\Programs\Python\Python310\lib\site-packages\django\template\defaulttags.py", line 854, in do_for
    nodelist_loop = parser.parse(
  File "C:\Users\fabro\AppData\Local\Programs\Python\Python310\lib\site-packages\django\template\base.py", line 507, in parse
    self.invalid_block_tag(token, command, parse_until)
  File "C:\Users\fabro\AppData\Local\Programs\Python\Python310\lib\site-packages\django\template\base.py", line 558, in invalid_block_tag
    raise self.error(
django.template.exceptions.TemplateSyntaxError: Invalid block tag on line 20: 'respone', expected 'empty' or 'endfor'. Did you forget to register or load this tag?
2022-11-11 17:36:52,757 Internal Server Error: /one_event/4
Traceback (most recent call last):
  File "C:\Users\fabro\AppData\Local\Programs\Python\Python310\lib\site-packages\django\template\base.py", line 505, in parse
    compile_func = self.tags[command]
KeyError: 'get_latest_response'

During handling of the above exception, another exception occurred:

Traceback (most recent call last):
  File "C:\Users\fabro\AppData\Local\Programs\Python\Python310\lib\site-packages\django\core\handlers\exception.py", line 55, in inner
    response = get_response(request)
  File "C:\Users\fabro\AppData\Local\Programs\Python\Python310\lib\site-packages\django\core\handlers\base.py", line 197, in _get_response
    response = wrapped_callback(request, *callback_args, **callback_kwargs)
  File "C:\PythonRemoteCZ7\Event_App\base\views.py", line 46, in event_detail
    return render(request, 'base/one_event.html', context)
  File "C:\Users\fabro\AppData\Local\Programs\Python\Python310\lib\site-packages\django\shortcuts.py", line 24, in render
    content = loader.render_to_string(template_name, context, request, using=using)
  File "C:\Users\fabro\AppData\Local\Programs\Python\Python310\lib\site-packages\django\template\loader.py", line 61, in render_to_string
    template = get_template(template_name, using=using)
  File "C:\Users\fabro\AppData\Local\Programs\Python\Python310\lib\site-packages\django\template\loader.py", line 15, in get_template
    return engine.get_template(template_name)
  File "C:\Users\fabro\AppData\Local\Programs\Python\Python310\lib\site-packages\django\template\backends\django.py", line 34, in get_template
    return Template(self.engine.get_template(template_name), self)
  File "C:\Users\fabro\AppData\Local\Programs\Python\Python310\lib\site-packages\django\template\engine.py", line 175, in get_template
    template, origin = self.find_template(template_name)
  File "C:\Users\fabro\AppData\Local\Programs\Python\Python310\lib\site-packages\django\template\engine.py", line 157, in find_template
    template = loader.get_template(name, skip=skip)
  File "C:\Users\fabro\AppData\Local\Programs\Python\Python310\lib\site-packages\django\template\loaders\cached.py", line 57, in get_template
    template = super().get_template(template_name, skip)
  File "C:\Users\fabro\AppData\Local\Programs\Python\Python310\lib\site-packages\django\template\loaders\base.py", line 28, in get_template
    return Template(
  File "C:\Users\fabro\AppData\Local\Programs\Python\Python310\lib\site-packages\django\template\base.py", line 154, in __init__
    self.nodelist = self.compile_nodelist()
  File "C:\Users\fabro\AppData\Local\Programs\Python\Python310\lib\site-packages\django\template\base.py", line 200, in compile_nodelist
    return parser.parse()
  File "C:\Users\fabro\AppData\Local\Programs\Python\Python310\lib\site-packages\django\template\base.py", line 513, in parse
    raise self.error(token, e)
  File "C:\Users\fabro\AppData\Local\Programs\Python\Python310\lib\site-packages\django\template\base.py", line 511, in parse
    compiled_result = compile_func(self, token)
  File "C:\Users\fabro\AppData\Local\Programs\Python\Python310\lib\site-packages\django\template\loader_tags.py", line 293, in do_extends
    nodelist = parser.parse()
  File "C:\Users\fabro\AppData\Local\Programs\Python\Python310\lib\site-packages\django\template\base.py", line 513, in parse
    raise self.error(token, e)
  File "C:\Users\fabro\AppData\Local\Programs\Python\Python310\lib\site-packages\django\template\base.py", line 511, in parse
    compiled_result = compile_func(self, token)
  File "C:\Users\fabro\AppData\Local\Programs\Python\Python310\lib\site-packages\django\template\loader_tags.py", line 232, in do_block
    nodelist = parser.parse(("endblock",))
  File "C:\Users\fabro\AppData\Local\Programs\Python\Python310\lib\site-packages\django\template\base.py", line 507, in parse
    self.invalid_block_tag(token, command, parse_until)
  File "C:\Users\fabro\AppData\Local\Programs\Python\Python310\lib\site-packages\django\template\base.py", line 558, in invalid_block_tag
    raise self.error(
django.template.exceptions.TemplateSyntaxError: Invalid block tag on line 25: 'get_latest_response', expected 'endblock'. Did you forget to register or load this tag?
2022-11-11 17:37:14,740 Internal Server Error: /one_event/4
Traceback (most recent call last):
  File "C:\Users\fabro\AppData\Local\Programs\Python\Python310\lib\site-packages\django\core\handlers\exception.py", line 55, in inner
    response = get_response(request)
  File "C:\Users\fabro\AppData\Local\Programs\Python\Python310\lib\site-packages\django\core\handlers\base.py", line 197, in _get_response
    response = wrapped_callback(request, *callback_args, **callback_kwargs)
  File "C:\PythonRemoteCZ7\Event_App\base\views.py", line 46, in event_detail
    return render(request, 'base/one_event.html', context)
  File "C:\Users\fabro\AppData\Local\Programs\Python\Python310\lib\site-packages\django\shortcuts.py", line 24, in render
    content = loader.render_to_string(template_name, context, request, using=using)
  File "C:\Users\fabro\AppData\Local\Programs\Python\Python310\lib\site-packages\django\template\loader.py", line 62, in render_to_string
    return template.render(context, request)
  File "C:\Users\fabro\AppData\Local\Programs\Python\Python310\lib\site-packages\django\template\backends\django.py", line 62, in render
    return self.template.render(context)
  File "C:\Users\fabro\AppData\Local\Programs\Python\Python310\lib\site-packages\django\template\base.py", line 175, in render
    return self._render(context)
  File "C:\Users\fabro\AppData\Local\Programs\Python\Python310\lib\site-packages\django\template\base.py", line 167, in _render
    return self.nodelist.render(context)
  File "C:\Users\fabro\AppData\Local\Programs\Python\Python310\lib\site-packages\django\template\base.py", line 1005, in render
    return SafeString("".join([node.render_annotated(context) for node in self]))
  File "C:\Users\fabro\AppData\Local\Programs\Python\Python310\lib\site-packages\django\template\base.py", line 1005, in <listcomp>
    return SafeString("".join([node.render_annotated(context) for node in self]))
  File "C:\Users\fabro\AppData\Local\Programs\Python\Python310\lib\site-packages\django\template\base.py", line 966, in render_annotated
    return self.render(context)
  File "C:\Users\fabro\AppData\Local\Programs\Python\Python310\lib\site-packages\django\template\loader_tags.py", line 157, in render
    return compiled_parent._render(context)
  File "C:\Users\fabro\AppData\Local\Programs\Python\Python310\lib\site-packages\django\template\base.py", line 167, in _render
    return self.nodelist.render(context)
  File "C:\Users\fabro\AppData\Local\Programs\Python\Python310\lib\site-packages\django\template\base.py", line 1005, in render
    return SafeString("".join([node.render_annotated(context) for node in self]))
  File "C:\Users\fabro\AppData\Local\Programs\Python\Python310\lib\site-packages\django\template\base.py", line 1005, in <listcomp>
    return SafeString("".join([node.render_annotated(context) for node in self]))
  File "C:\Users\fabro\AppData\Local\Programs\Python\Python310\lib\site-packages\django\template\base.py", line 966, in render_annotated
    return self.render(context)
  File "C:\Users\fabro\AppData\Local\Programs\Python\Python310\lib\site-packages\django\template\loader_tags.py", line 63, in render
    result = block.nodelist.render(context)
  File "C:\Users\fabro\AppData\Local\Programs\Python\Python310\lib\site-packages\django\template\base.py", line 1005, in render
    return SafeString("".join([node.render_annotated(context) for node in self]))
  File "C:\Users\fabro\AppData\Local\Programs\Python\Python310\lib\site-packages\django\template\base.py", line 1005, in <listcomp>
    return SafeString("".join([node.render_annotated(context) for node in self]))
  File "C:\Users\fabro\AppData\Local\Programs\Python\Python310\lib\site-packages\django\template\base.py", line 966, in render_annotated
    return self.render(context)
  File "C:\Users\fabro\AppData\Local\Programs\Python\Python310\lib\site-packages\django\template\defaulttags.py", line 322, in render
    return nodelist.render(context)
  File "C:\Users\fabro\AppData\Local\Programs\Python\Python310\lib\site-packages\django\template\base.py", line 1005, in render
    return SafeString("".join([node.render_annotated(context) for node in self]))
  File "C:\Users\fabro\AppData\Local\Programs\Python\Python310\lib\site-packages\django\template\base.py", line 1005, in <listcomp>
    return SafeString("".join([node.render_annotated(context) for node in self]))
  File "C:\Users\fabro\AppData\Local\Programs\Python\Python310\lib\site-packages\django\template\base.py", line 966, in render_annotated
    return self.render(context)
  File "C:\Users\fabro\AppData\Local\Programs\Python\Python310\lib\site-packages\django\template\defaulttags.py", line 472, in render
    url = reverse(view_name, args=args, kwargs=kwargs, current_app=current_app)
  File "C:\Users\fabro\AppData\Local\Programs\Python\Python310\lib\site-packages\django\urls\base.py", line 88, in reverse
    return resolver._reverse_with_prefix(view, prefix, *args, **kwargs)
  File "C:\Users\fabro\AppData\Local\Programs\Python\Python310\lib\site-packages\django\urls\resolvers.py", line 828, in _reverse_with_prefix
    raise NoReverseMatch(msg)
django.urls.exceptions.NoReverseMatch: Reverse for 'response' with arguments '('',)' not found. 1 pattern(s) tried: ['response/(?P<pk>[^/]+)\\Z']
2022-11-11 18:18:08,862 C:\PythonRemoteCZ7\Event_App\base\views.py changed, reloading.
2022-11-11 18:21:50,208 C:\PythonRemoteCZ7\Event_App\base\views.py changed, reloading.
2022-11-11 18:22:30,562 C:\PythonRemoteCZ7\Event_App\base\views.py changed, reloading.
2022-11-11 18:26:14,042 Internal Server Error: /one_event/2
Traceback (most recent call last):
  File "C:\Users\fabro\AppData\Local\Programs\Python\Python310\lib\site-packages\django\template\smartif.py", line 179, in translate_token
    op = OPERATORS[token]
KeyError: "'YES':"

During handling of the above exception, another exception occurred:

Traceback (most recent call last):
  File "C:\Users\fabro\AppData\Local\Programs\Python\Python310\lib\site-packages\django\core\handlers\exception.py", line 55, in inner
    response = get_response(request)
  File "C:\Users\fabro\AppData\Local\Programs\Python\Python310\lib\site-packages\django\core\handlers\base.py", line 197, in _get_response
    response = wrapped_callback(request, *callback_args, **callback_kwargs)
  File "C:\PythonRemoteCZ7\Event_App\base\views.py", line 46, in event_detail
    return render(request, 'base/one_event.html', context)
  File "C:\Users\fabro\AppData\Local\Programs\Python\Python310\lib\site-packages\django\shortcuts.py", line 24, in render
    content = loader.render_to_string(template_name, context, request, using=using)
  File "C:\Users\fabro\AppData\Local\Programs\Python\Python310\lib\site-packages\django\template\loader.py", line 61, in render_to_string
    template = get_template(template_name, using=using)
  File "C:\Users\fabro\AppData\Local\Programs\Python\Python310\lib\site-packages\django\template\loader.py", line 15, in get_template
    return engine.get_template(template_name)
  File "C:\Users\fabro\AppData\Local\Programs\Python\Python310\lib\site-packages\django\template\backends\django.py", line 34, in get_template
    return Template(self.engine.get_template(template_name), self)
  File "C:\Users\fabro\AppData\Local\Programs\Python\Python310\lib\site-packages\django\template\engine.py", line 175, in get_template
    template, origin = self.find_template(template_name)
  File "C:\Users\fabro\AppData\Local\Programs\Python\Python310\lib\site-packages\django\template\engine.py", line 157, in find_template
    template = loader.get_template(name, skip=skip)
  File "C:\Users\fabro\AppData\Local\Programs\Python\Python310\lib\site-packages\django\template\loaders\cached.py", line 57, in get_template
    template = super().get_template(template_name, skip)
  File "C:\Users\fabro\AppData\Local\Programs\Python\Python310\lib\site-packages\django\template\loaders\base.py", line 28, in get_template
    return Template(
  File "C:\Users\fabro\AppData\Local\Programs\Python\Python310\lib\site-packages\django\template\base.py", line 154, in __init__
    self.nodelist = self.compile_nodelist()
  File "C:\Users\fabro\AppData\Local\Programs\Python\Python310\lib\site-packages\django\template\base.py", line 200, in compile_nodelist
    return parser.parse()
  File "C:\Users\fabro\AppData\Local\Programs\Python\Python310\lib\site-packages\django\template\base.py", line 513, in parse
    raise self.error(token, e)
  File "C:\Users\fabro\AppData\Local\Programs\Python\Python310\lib\site-packages\django\template\base.py", line 511, in parse
    compiled_result = compile_func(self, token)
  File "C:\Users\fabro\AppData\Local\Programs\Python\Python310\lib\site-packages\django\template\loader_tags.py", line 293, in do_extends
    nodelist = parser.parse()
  File "C:\Users\fabro\AppData\Local\Programs\Python\Python310\lib\site-packages\django\template\base.py", line 513, in parse
    raise self.error(token, e)
  File "C:\Users\fabro\AppData\Local\Programs\Python\Python310\lib\site-packages\django\template\base.py", line 511, in parse
    compiled_result = compile_func(self, token)
  File "C:\Users\fabro\AppData\Local\Programs\Python\Python310\lib\site-packages\django\template\loader_tags.py", line 232, in do_block
    nodelist = parser.parse(("endblock",))
  File "C:\Users\fabro\AppData\Local\Programs\Python\Python310\lib\site-packages\django\template\base.py", line 513, in parse
    raise self.error(token, e)
  File "C:\Users\fabro\AppData\Local\Programs\Python\Python310\lib\site-packages\django\template\base.py", line 511, in parse
    compiled_result = compile_func(self, token)
  File "C:\Users\fabro\AppData\Local\Programs\Python\Python310\lib\site-packages\django\template\defaulttags.py", line 953, in do_if
    condition = TemplateIfParser(parser, bits).parse()
  File "C:\Users\fabro\AppData\Local\Programs\Python\Python310\lib\site-packages\django\template\defaulttags.py", line 886, in __init__
    super().__init__(*args, **kwargs)
  File "C:\Users\fabro\AppData\Local\Programs\Python\Python310\lib\site-packages\django\template\smartif.py", line 170, in __init__
    mapped_tokens.append(self.translate_token(token))
  File "C:\Users\fabro\AppData\Local\Programs\Python\Python310\lib\site-packages\django\template\smartif.py", line 181, in translate_token
    return self.create_var(token)
  File "C:\Users\fabro\AppData\Local\Programs\Python\Python310\lib\site-packages\django\template\defaulttags.py", line 889, in create_var
    return TemplateLiteral(self.template_parser.compile_filter(value), value)
  File "C:\Users\fabro\AppData\Local\Programs\Python\Python310\lib\site-packages\django\template\base.py", line 600, in compile_filter
    return FilterExpression(token, self)
  File "C:\Users\fabro\AppData\Local\Programs\Python\Python310\lib\site-packages\django\template\base.py", line 703, in __init__
    raise TemplateSyntaxError(
django.template.exceptions.TemplateSyntaxError: Could not parse the remainder: ':' from ''YES':'
2022-11-11 18:26:14,761 Internal Server Error: /one_event/2
Traceback (most recent call last):
  File "C:\Users\fabro\AppData\Local\Programs\Python\Python310\lib\site-packages\django\template\smartif.py", line 179, in translate_token
    op = OPERATORS[token]
KeyError: "'YES':"

During handling of the above exception, another exception occurred:

Traceback (most recent call last):
  File "C:\Users\fabro\AppData\Local\Programs\Python\Python310\lib\site-packages\django\core\handlers\exception.py", line 55, in inner
    response = get_response(request)
  File "C:\Users\fabro\AppData\Local\Programs\Python\Python310\lib\site-packages\django\core\handlers\base.py", line 197, in _get_response
    response = wrapped_callback(request, *callback_args, **callback_kwargs)
  File "C:\PythonRemoteCZ7\Event_App\base\views.py", line 46, in event_detail
    return render(request, 'base/one_event.html', context)
  File "C:\Users\fabro\AppData\Local\Programs\Python\Python310\lib\site-packages\django\shortcuts.py", line 24, in render
    content = loader.render_to_string(template_name, context, request, using=using)
  File "C:\Users\fabro\AppData\Local\Programs\Python\Python310\lib\site-packages\django\template\loader.py", line 61, in render_to_string
    template = get_template(template_name, using=using)
  File "C:\Users\fabro\AppData\Local\Programs\Python\Python310\lib\site-packages\django\template\loader.py", line 15, in get_template
    return engine.get_template(template_name)
  File "C:\Users\fabro\AppData\Local\Programs\Python\Python310\lib\site-packages\django\template\backends\django.py", line 34, in get_template
    return Template(self.engine.get_template(template_name), self)
  File "C:\Users\fabro\AppData\Local\Programs\Python\Python310\lib\site-packages\django\template\engine.py", line 175, in get_template
    template, origin = self.find_template(template_name)
  File "C:\Users\fabro\AppData\Local\Programs\Python\Python310\lib\site-packages\django\template\engine.py", line 157, in find_template
    template = loader.get_template(name, skip=skip)
  File "C:\Users\fabro\AppData\Local\Programs\Python\Python310\lib\site-packages\django\template\loaders\cached.py", line 57, in get_template
    template = super().get_template(template_name, skip)
  File "C:\Users\fabro\AppData\Local\Programs\Python\Python310\lib\site-packages\django\template\loaders\base.py", line 28, in get_template
    return Template(
  File "C:\Users\fabro\AppData\Local\Programs\Python\Python310\lib\site-packages\django\template\base.py", line 154, in __init__
    self.nodelist = self.compile_nodelist()
  File "C:\Users\fabro\AppData\Local\Programs\Python\Python310\lib\site-packages\django\template\base.py", line 200, in compile_nodelist
    return parser.parse()
  File "C:\Users\fabro\AppData\Local\Programs\Python\Python310\lib\site-packages\django\template\base.py", line 513, in parse
    raise self.error(token, e)
  File "C:\Users\fabro\AppData\Local\Programs\Python\Python310\lib\site-packages\django\template\base.py", line 511, in parse
    compiled_result = compile_func(self, token)
  File "C:\Users\fabro\AppData\Local\Programs\Python\Python310\lib\site-packages\django\template\loader_tags.py", line 293, in do_extends
    nodelist = parser.parse()
  File "C:\Users\fabro\AppData\Local\Programs\Python\Python310\lib\site-packages\django\template\base.py", line 513, in parse
    raise self.error(token, e)
  File "C:\Users\fabro\AppData\Local\Programs\Python\Python310\lib\site-packages\django\template\base.py", line 511, in parse
    compiled_result = compile_func(self, token)
  File "C:\Users\fabro\AppData\Local\Programs\Python\Python310\lib\site-packages\django\template\loader_tags.py", line 232, in do_block
    nodelist = parser.parse(("endblock",))
  File "C:\Users\fabro\AppData\Local\Programs\Python\Python310\lib\site-packages\django\template\base.py", line 513, in parse
    raise self.error(token, e)
  File "C:\Users\fabro\AppData\Local\Programs\Python\Python310\lib\site-packages\django\template\base.py", line 511, in parse
    compiled_result = compile_func(self, token)
  File "C:\Users\fabro\AppData\Local\Programs\Python\Python310\lib\site-packages\django\template\defaulttags.py", line 953, in do_if
    condition = TemplateIfParser(parser, bits).parse()
  File "C:\Users\fabro\AppData\Local\Programs\Python\Python310\lib\site-packages\django\template\defaulttags.py", line 886, in __init__
    super().__init__(*args, **kwargs)
  File "C:\Users\fabro\AppData\Local\Programs\Python\Python310\lib\site-packages\django\template\smartif.py", line 170, in __init__
    mapped_tokens.append(self.translate_token(token))
  File "C:\Users\fabro\AppData\Local\Programs\Python\Python310\lib\site-packages\django\template\smartif.py", line 181, in translate_token
    return self.create_var(token)
  File "C:\Users\fabro\AppData\Local\Programs\Python\Python310\lib\site-packages\django\template\defaulttags.py", line 889, in create_var
    return TemplateLiteral(self.template_parser.compile_filter(value), value)
  File "C:\Users\fabro\AppData\Local\Programs\Python\Python310\lib\site-packages\django\template\base.py", line 600, in compile_filter
    return FilterExpression(token, self)
  File "C:\Users\fabro\AppData\Local\Programs\Python\Python310\lib\site-packages\django\template\base.py", line 703, in __init__
    raise TemplateSyntaxError(
django.template.exceptions.TemplateSyntaxError: Could not parse the remainder: ':' from ''YES':'
2022-11-11 18:26:51,603 Internal Server Error: /one_event/2
Traceback (most recent call last):
  File "C:\Users\fabro\AppData\Local\Programs\Python\Python310\lib\site-packages\django\template\smartif.py", line 179, in translate_token
    op = OPERATORS[token]
KeyError: "latest_response=='YES'"

During handling of the above exception, another exception occurred:

Traceback (most recent call last):
  File "C:\Users\fabro\AppData\Local\Programs\Python\Python310\lib\site-packages\django\core\handlers\exception.py", line 55, in inner
    response = get_response(request)
  File "C:\Users\fabro\AppData\Local\Programs\Python\Python310\lib\site-packages\django\core\handlers\base.py", line 197, in _get_response
    response = wrapped_callback(request, *callback_args, **callback_kwargs)
  File "C:\PythonRemoteCZ7\Event_App\base\views.py", line 46, in event_detail
    return render(request, 'base/one_event.html', context)
  File "C:\Users\fabro\AppData\Local\Programs\Python\Python310\lib\site-packages\django\shortcuts.py", line 24, in render
    content = loader.render_to_string(template_name, context, request, using=using)
  File "C:\Users\fabro\AppData\Local\Programs\Python\Python310\lib\site-packages\django\template\loader.py", line 61, in render_to_string
    template = get_template(template_name, using=using)
  File "C:\Users\fabro\AppData\Local\Programs\Python\Python310\lib\site-packages\django\template\loader.py", line 15, in get_template
    return engine.get_template(template_name)
  File "C:\Users\fabro\AppData\Local\Programs\Python\Python310\lib\site-packages\django\template\backends\django.py", line 34, in get_template
    return Template(self.engine.get_template(template_name), self)
  File "C:\Users\fabro\AppData\Local\Programs\Python\Python310\lib\site-packages\django\template\engine.py", line 175, in get_template
    template, origin = self.find_template(template_name)
  File "C:\Users\fabro\AppData\Local\Programs\Python\Python310\lib\site-packages\django\template\engine.py", line 157, in find_template
    template = loader.get_template(name, skip=skip)
  File "C:\Users\fabro\AppData\Local\Programs\Python\Python310\lib\site-packages\django\template\loaders\cached.py", line 57, in get_template
    template = super().get_template(template_name, skip)
  File "C:\Users\fabro\AppData\Local\Programs\Python\Python310\lib\site-packages\django\template\loaders\base.py", line 28, in get_template
    return Template(
  File "C:\Users\fabro\AppData\Local\Programs\Python\Python310\lib\site-packages\django\template\base.py", line 154, in __init__
    self.nodelist = self.compile_nodelist()
  File "C:\Users\fabro\AppData\Local\Programs\Python\Python310\lib\site-packages\django\template\base.py", line 200, in compile_nodelist
    return parser.parse()
  File "C:\Users\fabro\AppData\Local\Programs\Python\Python310\lib\site-packages\django\template\base.py", line 513, in parse
    raise self.error(token, e)
  File "C:\Users\fabro\AppData\Local\Programs\Python\Python310\lib\site-packages\django\template\base.py", line 511, in parse
    compiled_result = compile_func(self, token)
  File "C:\Users\fabro\AppData\Local\Programs\Python\Python310\lib\site-packages\django\template\loader_tags.py", line 293, in do_extends
    nodelist = parser.parse()
  File "C:\Users\fabro\AppData\Local\Programs\Python\Python310\lib\site-packages\django\template\base.py", line 513, in parse
    raise self.error(token, e)
  File "C:\Users\fabro\AppData\Local\Programs\Python\Python310\lib\site-packages\django\template\base.py", line 511, in parse
    compiled_result = compile_func(self, token)
  File "C:\Users\fabro\AppData\Local\Programs\Python\Python310\lib\site-packages\django\template\loader_tags.py", line 232, in do_block
    nodelist = parser.parse(("endblock",))
  File "C:\Users\fabro\AppData\Local\Programs\Python\Python310\lib\site-packages\django\template\base.py", line 513, in parse
    raise self.error(token, e)
  File "C:\Users\fabro\AppData\Local\Programs\Python\Python310\lib\site-packages\django\template\base.py", line 511, in parse
    compiled_result = compile_func(self, token)
  File "C:\Users\fabro\AppData\Local\Programs\Python\Python310\lib\site-packages\django\template\defaulttags.py", line 953, in do_if
    condition = TemplateIfParser(parser, bits).parse()
  File "C:\Users\fabro\AppData\Local\Programs\Python\Python310\lib\site-packages\django\template\defaulttags.py", line 886, in __init__
    super().__init__(*args, **kwargs)
  File "C:\Users\fabro\AppData\Local\Programs\Python\Python310\lib\site-packages\django\template\smartif.py", line 170, in __init__
    mapped_tokens.append(self.translate_token(token))
  File "C:\Users\fabro\AppData\Local\Programs\Python\Python310\lib\site-packages\django\template\smartif.py", line 181, in translate_token
    return self.create_var(token)
  File "C:\Users\fabro\AppData\Local\Programs\Python\Python310\lib\site-packages\django\template\defaulttags.py", line 889, in create_var
    return TemplateLiteral(self.template_parser.compile_filter(value), value)
  File "C:\Users\fabro\AppData\Local\Programs\Python\Python310\lib\site-packages\django\template\base.py", line 600, in compile_filter
    return FilterExpression(token, self)
  File "C:\Users\fabro\AppData\Local\Programs\Python\Python310\lib\site-packages\django\template\base.py", line 703, in __init__
    raise TemplateSyntaxError(
django.template.exceptions.TemplateSyntaxError: Could not parse the remainder: '=='YES'' from 'latest_response=='YES''
2022-11-11 18:38:45,141 C:\PythonRemoteCZ7\Event_App\base\views.py changed, reloading.
2022-11-11 18:40:37,396 C:\PythonRemoteCZ7\Event_App\base\views.py changed, reloading.
2022-11-11 18:55:58,975 Internal Server Error: /one_event/2
Traceback (most recent call last):
  File "C:\Users\fabro\AppData\Local\Programs\Python\Python310\lib\site-packages\django\core\handlers\exception.py", line 55, in inner
    response = get_response(request)
  File "C:\Users\fabro\AppData\Local\Programs\Python\Python310\lib\site-packages\django\core\handlers\base.py", line 197, in _get_response
    response = wrapped_callback(request, *callback_args, **callback_kwargs)
  File "C:\PythonRemoteCZ7\Event_App\base\views.py", line 46, in event_detail
    return render(request, 'base/one_event.html', context)
  File "C:\Users\fabro\AppData\Local\Programs\Python\Python310\lib\site-packages\django\shortcuts.py", line 24, in render
    content = loader.render_to_string(template_name, context, request, using=using)
  File "C:\Users\fabro\AppData\Local\Programs\Python\Python310\lib\site-packages\django\template\loader.py", line 61, in render_to_string
    template = get_template(template_name, using=using)
  File "C:\Users\fabro\AppData\Local\Programs\Python\Python310\lib\site-packages\django\template\loader.py", line 15, in get_template
    return engine.get_template(template_name)
  File "C:\Users\fabro\AppData\Local\Programs\Python\Python310\lib\site-packages\django\template\backends\django.py", line 34, in get_template
    return Template(self.engine.get_template(template_name), self)
  File "C:\Users\fabro\AppData\Local\Programs\Python\Python310\lib\site-packages\django\template\engine.py", line 175, in get_template
    template, origin = self.find_template(template_name)
  File "C:\Users\fabro\AppData\Local\Programs\Python\Python310\lib\site-packages\django\template\engine.py", line 157, in find_template
    template = loader.get_template(name, skip=skip)
  File "C:\Users\fabro\AppData\Local\Programs\Python\Python310\lib\site-packages\django\template\loaders\cached.py", line 57, in get_template
    template = super().get_template(template_name, skip)
  File "C:\Users\fabro\AppData\Local\Programs\Python\Python310\lib\site-packages\django\template\loaders\base.py", line 28, in get_template
    return Template(
  File "C:\Users\fabro\AppData\Local\Programs\Python\Python310\lib\site-packages\django\template\base.py", line 154, in __init__
    self.nodelist = self.compile_nodelist()
  File "C:\Users\fabro\AppData\Local\Programs\Python\Python310\lib\site-packages\django\template\base.py", line 200, in compile_nodelist
    return parser.parse()
  File "C:\Users\fabro\AppData\Local\Programs\Python\Python310\lib\site-packages\django\template\base.py", line 513, in parse
    raise self.error(token, e)
  File "C:\Users\fabro\AppData\Local\Programs\Python\Python310\lib\site-packages\django\template\base.py", line 511, in parse
    compiled_result = compile_func(self, token)
  File "C:\Users\fabro\AppData\Local\Programs\Python\Python310\lib\site-packages\django\template\loader_tags.py", line 293, in do_extends
    nodelist = parser.parse()
  File "C:\Users\fabro\AppData\Local\Programs\Python\Python310\lib\site-packages\django\template\base.py", line 513, in parse
    raise self.error(token, e)
  File "C:\Users\fabro\AppData\Local\Programs\Python\Python310\lib\site-packages\django\template\base.py", line 511, in parse
    compiled_result = compile_func(self, token)
  File "C:\Users\fabro\AppData\Local\Programs\Python\Python310\lib\site-packages\django\template\loader_tags.py", line 232, in do_block
    nodelist = parser.parse(("endblock",))
  File "C:\Users\fabro\AppData\Local\Programs\Python\Python310\lib\site-packages\django\template\base.py", line 484, in parse
    raise self.error(token, e)
  File "C:\Users\fabro\AppData\Local\Programs\Python\Python310\lib\site-packages\django\template\base.py", line 482, in parse
    filter_expression = self.compile_filter(token.contents)
  File "C:\Users\fabro\AppData\Local\Programs\Python\Python310\lib\site-packages\django\template\base.py", line 600, in compile_filter
    return FilterExpression(token, self)
  File "C:\Users\fabro\AppData\Local\Programs\Python\Python310\lib\site-packages\django\template\base.py", line 703, in __init__
    raise TemplateSyntaxError(
django.template.exceptions.TemplateSyntaxError: Could not parse the remainder: '(latest_response)' from 'type(latest_response)'
2022-11-12 09:29:23,669 Not Found: /favicon.ico
2022-11-12 09:53:37,925 Internal Server Error: /one_event/4
Traceback (most recent call last):
  File "C:\Users\fabro\AppData\Local\Programs\Python\Python310\lib\site-packages\django\db\models\fields\__init__.py", line 2018, in get_prep_value
    return int(value)
TypeError: int() argument must be a string, a bytes-like object or a real number, not 'SimpleLazyObject'

The above exception was the direct cause of the following exception:

Traceback (most recent call last):
  File "C:\Users\fabro\AppData\Local\Programs\Python\Python310\lib\site-packages\django\core\handlers\exception.py", line 55, in inner
    response = get_response(request)
  File "C:\Users\fabro\AppData\Local\Programs\Python\Python310\lib\site-packages\django\core\handlers\base.py", line 197, in _get_response
    response = wrapped_callback(request, *callback_args, **callback_kwargs)
  File "C:\PythonRemoteCZ7\Event_App\base\views.py", line 31, in event_detail
    latest_response = EventResponse.objects.filter(
  File "C:\Users\fabro\AppData\Local\Programs\Python\Python310\lib\site-packages\django\db\models\manager.py", line 85, in manager_method
    return getattr(self.get_queryset(), name)(*args, **kwargs)
  File "C:\Users\fabro\AppData\Local\Programs\Python\Python310\lib\site-packages\django\db\models\query.py", line 1420, in filter
    return self._filter_or_exclude(False, args, kwargs)
  File "C:\Users\fabro\AppData\Local\Programs\Python\Python310\lib\site-packages\django\db\models\query.py", line 1438, in _filter_or_exclude
    clone._filter_or_exclude_inplace(negate, args, kwargs)
  File "C:\Users\fabro\AppData\Local\Programs\Python\Python310\lib\site-packages\django\db\models\query.py", line 1445, in _filter_or_exclude_inplace
    self._query.add_q(Q(*args, **kwargs))
  File "C:\Users\fabro\AppData\Local\Programs\Python\Python310\lib\site-packages\django\db\models\sql\query.py", line 1532, in add_q
    clause, _ = self._add_q(q_object, self.used_aliases)
  File "C:\Users\fabro\AppData\Local\Programs\Python\Python310\lib\site-packages\django\db\models\sql\query.py", line 1562, in _add_q
    child_clause, needed_inner = self.build_filter(
  File "C:\Users\fabro\AppData\Local\Programs\Python\Python310\lib\site-packages\django\db\models\sql\query.py", line 1478, in build_filter
    condition = self.build_lookup(lookups, col, value)
  File "C:\Users\fabro\AppData\Local\Programs\Python\Python310\lib\site-packages\django\db\models\sql\query.py", line 1303, in build_lookup
    lookup = lookup_class(lhs, rhs)
  File "C:\Users\fabro\AppData\Local\Programs\Python\Python310\lib\site-packages\django\db\models\lookups.py", line 27, in __init__
    self.rhs = self.get_prep_lookup()
  File "C:\Users\fabro\AppData\Local\Programs\Python\Python310\lib\site-packages\django\db\models\fields\related_lookups.py", line 166, in get_prep_lookup
    self.rhs = target_field.get_prep_value(self.rhs)
  File "C:\Users\fabro\AppData\Local\Programs\Python\Python310\lib\site-packages\django\db\models\fields\__init__.py", line 2020, in get_prep_value
    raise e.__class__(
TypeError: Field 'id' expected a number but got <SimpleLazyObject: <django.contrib.auth.models.AnonymousUser object at 0x00000253F9BF8250>>.
2022-11-12 09:54:37,139 Internal Server Error: /one_event/4
Traceback (most recent call last):
  File "C:\Users\fabro\AppData\Local\Programs\Python\Python310\lib\site-packages\django\db\models\fields\__init__.py", line 2018, in get_prep_value
    return int(value)
TypeError: int() argument must be a string, a bytes-like object or a real number, not 'SimpleLazyObject'

The above exception was the direct cause of the following exception:

Traceback (most recent call last):
  File "C:\Users\fabro\AppData\Local\Programs\Python\Python310\lib\site-packages\django\core\handlers\exception.py", line 55, in inner
    response = get_response(request)
  File "C:\Users\fabro\AppData\Local\Programs\Python\Python310\lib\site-packages\django\core\handlers\base.py", line 197, in _get_response
    response = wrapped_callback(request, *callback_args, **callback_kwargs)
  File "C:\PythonRemoteCZ7\Event_App\base\views.py", line 31, in event_detail
    latest_response = EventResponse.objects.filter(
  File "C:\Users\fabro\AppData\Local\Programs\Python\Python310\lib\site-packages\django\db\models\manager.py", line 85, in manager_method
    return getattr(self.get_queryset(), name)(*args, **kwargs)
  File "C:\Users\fabro\AppData\Local\Programs\Python\Python310\lib\site-packages\django\db\models\query.py", line 1420, in filter
    return self._filter_or_exclude(False, args, kwargs)
  File "C:\Users\fabro\AppData\Local\Programs\Python\Python310\lib\site-packages\django\db\models\query.py", line 1438, in _filter_or_exclude
    clone._filter_or_exclude_inplace(negate, args, kwargs)
  File "C:\Users\fabro\AppData\Local\Programs\Python\Python310\lib\site-packages\django\db\models\query.py", line 1445, in _filter_or_exclude_inplace
    self._query.add_q(Q(*args, **kwargs))
  File "C:\Users\fabro\AppData\Local\Programs\Python\Python310\lib\site-packages\django\db\models\sql\query.py", line 1532, in add_q
    clause, _ = self._add_q(q_object, self.used_aliases)
  File "C:\Users\fabro\AppData\Local\Programs\Python\Python310\lib\site-packages\django\db\models\sql\query.py", line 1562, in _add_q
    child_clause, needed_inner = self.build_filter(
  File "C:\Users\fabro\AppData\Local\Programs\Python\Python310\lib\site-packages\django\db\models\sql\query.py", line 1478, in build_filter
    condition = self.build_lookup(lookups, col, value)
  File "C:\Users\fabro\AppData\Local\Programs\Python\Python310\lib\site-packages\django\db\models\sql\query.py", line 1303, in build_lookup
    lookup = lookup_class(lhs, rhs)
  File "C:\Users\fabro\AppData\Local\Programs\Python\Python310\lib\site-packages\django\db\models\lookups.py", line 27, in __init__
    self.rhs = self.get_prep_lookup()
  File "C:\Users\fabro\AppData\Local\Programs\Python\Python310\lib\site-packages\django\db\models\fields\related_lookups.py", line 166, in get_prep_lookup
    self.rhs = target_field.get_prep_value(self.rhs)
  File "C:\Users\fabro\AppData\Local\Programs\Python\Python310\lib\site-packages\django\db\models\fields\__init__.py", line 2020, in get_prep_value
    raise e.__class__(
TypeError: Field 'id' expected a number but got <SimpleLazyObject: <django.contrib.auth.models.AnonymousUser object at 0x00000253F9B57700>>.
2022-11-12 09:54:38,269 Internal Server Error: /one_event/4
Traceback (most recent call last):
  File "C:\Users\fabro\AppData\Local\Programs\Python\Python310\lib\site-packages\django\db\models\fields\__init__.py", line 2018, in get_prep_value
    return int(value)
TypeError: int() argument must be a string, a bytes-like object or a real number, not 'SimpleLazyObject'

The above exception was the direct cause of the following exception:

Traceback (most recent call last):
  File "C:\Users\fabro\AppData\Local\Programs\Python\Python310\lib\site-packages\django\core\handlers\exception.py", line 55, in inner
    response = get_response(request)
  File "C:\Users\fabro\AppData\Local\Programs\Python\Python310\lib\site-packages\django\core\handlers\base.py", line 197, in _get_response
    response = wrapped_callback(request, *callback_args, **callback_kwargs)
  File "C:\PythonRemoteCZ7\Event_App\base\views.py", line 31, in event_detail
    latest_response = EventResponse.objects.filter(
  File "C:\Users\fabro\AppData\Local\Programs\Python\Python310\lib\site-packages\django\db\models\manager.py", line 85, in manager_method
    return getattr(self.get_queryset(), name)(*args, **kwargs)
  File "C:\Users\fabro\AppData\Local\Programs\Python\Python310\lib\site-packages\django\db\models\query.py", line 1420, in filter
    return self._filter_or_exclude(False, args, kwargs)
  File "C:\Users\fabro\AppData\Local\Programs\Python\Python310\lib\site-packages\django\db\models\query.py", line 1438, in _filter_or_exclude
    clone._filter_or_exclude_inplace(negate, args, kwargs)
  File "C:\Users\fabro\AppData\Local\Programs\Python\Python310\lib\site-packages\django\db\models\query.py", line 1445, in _filter_or_exclude_inplace
    self._query.add_q(Q(*args, **kwargs))
  File "C:\Users\fabro\AppData\Local\Programs\Python\Python310\lib\site-packages\django\db\models\sql\query.py", line 1532, in add_q
    clause, _ = self._add_q(q_object, self.used_aliases)
  File "C:\Users\fabro\AppData\Local\Programs\Python\Python310\lib\site-packages\django\db\models\sql\query.py", line 1562, in _add_q
    child_clause, needed_inner = self.build_filter(
  File "C:\Users\fabro\AppData\Local\Programs\Python\Python310\lib\site-packages\django\db\models\sql\query.py", line 1478, in build_filter
    condition = self.build_lookup(lookups, col, value)
  File "C:\Users\fabro\AppData\Local\Programs\Python\Python310\lib\site-packages\django\db\models\sql\query.py", line 1303, in build_lookup
    lookup = lookup_class(lhs, rhs)
  File "C:\Users\fabro\AppData\Local\Programs\Python\Python310\lib\site-packages\django\db\models\lookups.py", line 27, in __init__
    self.rhs = self.get_prep_lookup()
  File "C:\Users\fabro\AppData\Local\Programs\Python\Python310\lib\site-packages\django\db\models\fields\related_lookups.py", line 166, in get_prep_lookup
    self.rhs = target_field.get_prep_value(self.rhs)
  File "C:\Users\fabro\AppData\Local\Programs\Python\Python310\lib\site-packages\django\db\models\fields\__init__.py", line 2020, in get_prep_value
    raise e.__class__(
TypeError: Field 'id' expected a number but got <SimpleLazyObject: <django.contrib.auth.models.AnonymousUser object at 0x00000253F9BF8910>>.
2022-11-12 09:55:18,835 Internal Server Error: /one_event/4
Traceback (most recent call last):
  File "C:\Users\fabro\AppData\Local\Programs\Python\Python310\lib\site-packages\django\db\models\fields\__init__.py", line 2018, in get_prep_value
    return int(value)
TypeError: int() argument must be a string, a bytes-like object or a real number, not 'SimpleLazyObject'

The above exception was the direct cause of the following exception:

Traceback (most recent call last):
  File "C:\Users\fabro\AppData\Local\Programs\Python\Python310\lib\site-packages\django\core\handlers\exception.py", line 55, in inner
    response = get_response(request)
  File "C:\Users\fabro\AppData\Local\Programs\Python\Python310\lib\site-packages\django\core\handlers\base.py", line 197, in _get_response
    response = wrapped_callback(request, *callback_args, **callback_kwargs)
  File "C:\PythonRemoteCZ7\Event_App\base\views.py", line 31, in event_detail
    latest_response = EventResponse.objects.filter(
  File "C:\Users\fabro\AppData\Local\Programs\Python\Python310\lib\site-packages\django\db\models\manager.py", line 85, in manager_method
    return getattr(self.get_queryset(), name)(*args, **kwargs)
  File "C:\Users\fabro\AppData\Local\Programs\Python\Python310\lib\site-packages\django\db\models\query.py", line 1420, in filter
    return self._filter_or_exclude(False, args, kwargs)
  File "C:\Users\fabro\AppData\Local\Programs\Python\Python310\lib\site-packages\django\db\models\query.py", line 1438, in _filter_or_exclude
    clone._filter_or_exclude_inplace(negate, args, kwargs)
  File "C:\Users\fabro\AppData\Local\Programs\Python\Python310\lib\site-packages\django\db\models\query.py", line 1445, in _filter_or_exclude_inplace
    self._query.add_q(Q(*args, **kwargs))
  File "C:\Users\fabro\AppData\Local\Programs\Python\Python310\lib\site-packages\django\db\models\sql\query.py", line 1532, in add_q
    clause, _ = self._add_q(q_object, self.used_aliases)
  File "C:\Users\fabro\AppData\Local\Programs\Python\Python310\lib\site-packages\django\db\models\sql\query.py", line 1562, in _add_q
    child_clause, needed_inner = self.build_filter(
  File "C:\Users\fabro\AppData\Local\Programs\Python\Python310\lib\site-packages\django\db\models\sql\query.py", line 1478, in build_filter
    condition = self.build_lookup(lookups, col, value)
  File "C:\Users\fabro\AppData\Local\Programs\Python\Python310\lib\site-packages\django\db\models\sql\query.py", line 1303, in build_lookup
    lookup = lookup_class(lhs, rhs)
  File "C:\Users\fabro\AppData\Local\Programs\Python\Python310\lib\site-packages\django\db\models\lookups.py", line 27, in __init__
    self.rhs = self.get_prep_lookup()
  File "C:\Users\fabro\AppData\Local\Programs\Python\Python310\lib\site-packages\django\db\models\fields\related_lookups.py", line 166, in get_prep_lookup
    self.rhs = target_field.get_prep_value(self.rhs)
  File "C:\Users\fabro\AppData\Local\Programs\Python\Python310\lib\site-packages\django\db\models\fields\__init__.py", line 2020, in get_prep_value
    raise e.__class__(
TypeError: Field 'id' expected a number but got <SimpleLazyObject: <django.contrib.auth.models.AnonymousUser object at 0x00000253F9C40A00>>.
2022-11-12 09:57:22,867 Internal Server Error: /one_event/4
Traceback (most recent call last):
  File "C:\Users\fabro\AppData\Local\Programs\Python\Python310\lib\site-packages\django\db\models\fields\__init__.py", line 2018, in get_prep_value
    return int(value)
TypeError: int() argument must be a string, a bytes-like object or a real number, not 'SimpleLazyObject'

The above exception was the direct cause of the following exception:

Traceback (most recent call last):
  File "C:\Users\fabro\AppData\Local\Programs\Python\Python310\lib\site-packages\django\core\handlers\exception.py", line 55, in inner
    response = get_response(request)
  File "C:\Users\fabro\AppData\Local\Programs\Python\Python310\lib\site-packages\django\core\handlers\base.py", line 197, in _get_response
    response = wrapped_callback(request, *callback_args, **callback_kwargs)
  File "C:\PythonRemoteCZ7\Event_App\base\views.py", line 31, in event_detail
    latest_response = EventResponse.objects.filter(
  File "C:\Users\fabro\AppData\Local\Programs\Python\Python310\lib\site-packages\django\db\models\manager.py", line 85, in manager_method
    return getattr(self.get_queryset(), name)(*args, **kwargs)
  File "C:\Users\fabro\AppData\Local\Programs\Python\Python310\lib\site-packages\django\db\models\query.py", line 1420, in filter
    return self._filter_or_exclude(False, args, kwargs)
  File "C:\Users\fabro\AppData\Local\Programs\Python\Python310\lib\site-packages\django\db\models\query.py", line 1438, in _filter_or_exclude
    clone._filter_or_exclude_inplace(negate, args, kwargs)
  File "C:\Users\fabro\AppData\Local\Programs\Python\Python310\lib\site-packages\django\db\models\query.py", line 1445, in _filter_or_exclude_inplace
    self._query.add_q(Q(*args, **kwargs))
  File "C:\Users\fabro\AppData\Local\Programs\Python\Python310\lib\site-packages\django\db\models\sql\query.py", line 1532, in add_q
    clause, _ = self._add_q(q_object, self.used_aliases)
  File "C:\Users\fabro\AppData\Local\Programs\Python\Python310\lib\site-packages\django\db\models\sql\query.py", line 1562, in _add_q
    child_clause, needed_inner = self.build_filter(
  File "C:\Users\fabro\AppData\Local\Programs\Python\Python310\lib\site-packages\django\db\models\sql\query.py", line 1478, in build_filter
    condition = self.build_lookup(lookups, col, value)
  File "C:\Users\fabro\AppData\Local\Programs\Python\Python310\lib\site-packages\django\db\models\sql\query.py", line 1303, in build_lookup
    lookup = lookup_class(lhs, rhs)
  File "C:\Users\fabro\AppData\Local\Programs\Python\Python310\lib\site-packages\django\db\models\lookups.py", line 27, in __init__
    self.rhs = self.get_prep_lookup()
  File "C:\Users\fabro\AppData\Local\Programs\Python\Python310\lib\site-packages\django\db\models\fields\related_lookups.py", line 166, in get_prep_lookup
    self.rhs = target_field.get_prep_value(self.rhs)
  File "C:\Users\fabro\AppData\Local\Programs\Python\Python310\lib\site-packages\django\db\models\fields\__init__.py", line 2020, in get_prep_value
    raise e.__class__(
TypeError: Field 'id' expected a number but got <SimpleLazyObject: <django.contrib.auth.models.AnonymousUser object at 0x00000253F9BFA5F0>>.
2022-11-12 09:57:23,896 Internal Server Error: /one_event/4
Traceback (most recent call last):
  File "C:\Users\fabro\AppData\Local\Programs\Python\Python310\lib\site-packages\django\db\models\fields\__init__.py", line 2018, in get_prep_value
    return int(value)
TypeError: int() argument must be a string, a bytes-like object or a real number, not 'SimpleLazyObject'

The above exception was the direct cause of the following exception:

Traceback (most recent call last):
  File "C:\Users\fabro\AppData\Local\Programs\Python\Python310\lib\site-packages\django\core\handlers\exception.py", line 55, in inner
    response = get_response(request)
  File "C:\Users\fabro\AppData\Local\Programs\Python\Python310\lib\site-packages\django\core\handlers\base.py", line 197, in _get_response
    response = wrapped_callback(request, *callback_args, **callback_kwargs)
  File "C:\PythonRemoteCZ7\Event_App\base\views.py", line 31, in event_detail
    latest_response = EventResponse.objects.filter(
  File "C:\Users\fabro\AppData\Local\Programs\Python\Python310\lib\site-packages\django\db\models\manager.py", line 85, in manager_method
    return getattr(self.get_queryset(), name)(*args, **kwargs)
  File "C:\Users\fabro\AppData\Local\Programs\Python\Python310\lib\site-packages\django\db\models\query.py", line 1420, in filter
    return self._filter_or_exclude(False, args, kwargs)
  File "C:\Users\fabro\AppData\Local\Programs\Python\Python310\lib\site-packages\django\db\models\query.py", line 1438, in _filter_or_exclude
    clone._filter_or_exclude_inplace(negate, args, kwargs)
  File "C:\Users\fabro\AppData\Local\Programs\Python\Python310\lib\site-packages\django\db\models\query.py", line 1445, in _filter_or_exclude_inplace
    self._query.add_q(Q(*args, **kwargs))
  File "C:\Users\fabro\AppData\Local\Programs\Python\Python310\lib\site-packages\django\db\models\sql\query.py", line 1532, in add_q
    clause, _ = self._add_q(q_object, self.used_aliases)
  File "C:\Users\fabro\AppData\Local\Programs\Python\Python310\lib\site-packages\django\db\models\sql\query.py", line 1562, in _add_q
    child_clause, needed_inner = self.build_filter(
  File "C:\Users\fabro\AppData\Local\Programs\Python\Python310\lib\site-packages\django\db\models\sql\query.py", line 1478, in build_filter
    condition = self.build_lookup(lookups, col, value)
  File "C:\Users\fabro\AppData\Local\Programs\Python\Python310\lib\site-packages\django\db\models\sql\query.py", line 1303, in build_lookup
    lookup = lookup_class(lhs, rhs)
  File "C:\Users\fabro\AppData\Local\Programs\Python\Python310\lib\site-packages\django\db\models\lookups.py", line 27, in __init__
    self.rhs = self.get_prep_lookup()
  File "C:\Users\fabro\AppData\Local\Programs\Python\Python310\lib\site-packages\django\db\models\fields\related_lookups.py", line 166, in get_prep_lookup
    self.rhs = target_field.get_prep_value(self.rhs)
  File "C:\Users\fabro\AppData\Local\Programs\Python\Python310\lib\site-packages\django\db\models\fields\__init__.py", line 2020, in get_prep_value
    raise e.__class__(
TypeError: Field 'id' expected a number but got <SimpleLazyObject: <django.contrib.auth.models.AnonymousUser object at 0x00000253FA6F0A00>>.
2022-11-12 09:57:24,174 Internal Server Error: /one_event/4
Traceback (most recent call last):
  File "C:\Users\fabro\AppData\Local\Programs\Python\Python310\lib\site-packages\django\db\models\fields\__init__.py", line 2018, in get_prep_value
    return int(value)
TypeError: int() argument must be a string, a bytes-like object or a real number, not 'SimpleLazyObject'

The above exception was the direct cause of the following exception:

Traceback (most recent call last):
  File "C:\Users\fabro\AppData\Local\Programs\Python\Python310\lib\site-packages\django\core\handlers\exception.py", line 55, in inner
    response = get_response(request)
  File "C:\Users\fabro\AppData\Local\Programs\Python\Python310\lib\site-packages\django\core\handlers\base.py", line 197, in _get_response
    response = wrapped_callback(request, *callback_args, **callback_kwargs)
  File "C:\PythonRemoteCZ7\Event_App\base\views.py", line 31, in event_detail
    latest_response = EventResponse.objects.filter(
  File "C:\Users\fabro\AppData\Local\Programs\Python\Python310\lib\site-packages\django\db\models\manager.py", line 85, in manager_method
    return getattr(self.get_queryset(), name)(*args, **kwargs)
  File "C:\Users\fabro\AppData\Local\Programs\Python\Python310\lib\site-packages\django\db\models\query.py", line 1420, in filter
    return self._filter_or_exclude(False, args, kwargs)
  File "C:\Users\fabro\AppData\Local\Programs\Python\Python310\lib\site-packages\django\db\models\query.py", line 1438, in _filter_or_exclude
    clone._filter_or_exclude_inplace(negate, args, kwargs)
  File "C:\Users\fabro\AppData\Local\Programs\Python\Python310\lib\site-packages\django\db\models\query.py", line 1445, in _filter_or_exclude_inplace
    self._query.add_q(Q(*args, **kwargs))
  File "C:\Users\fabro\AppData\Local\Programs\Python\Python310\lib\site-packages\django\db\models\sql\query.py", line 1532, in add_q
    clause, _ = self._add_q(q_object, self.used_aliases)
  File "C:\Users\fabro\AppData\Local\Programs\Python\Python310\lib\site-packages\django\db\models\sql\query.py", line 1562, in _add_q
    child_clause, needed_inner = self.build_filter(
  File "C:\Users\fabro\AppData\Local\Programs\Python\Python310\lib\site-packages\django\db\models\sql\query.py", line 1478, in build_filter
    condition = self.build_lookup(lookups, col, value)
  File "C:\Users\fabro\AppData\Local\Programs\Python\Python310\lib\site-packages\django\db\models\sql\query.py", line 1303, in build_lookup
    lookup = lookup_class(lhs, rhs)
  File "C:\Users\fabro\AppData\Local\Programs\Python\Python310\lib\site-packages\django\db\models\lookups.py", line 27, in __init__
    self.rhs = self.get_prep_lookup()
  File "C:\Users\fabro\AppData\Local\Programs\Python\Python310\lib\site-packages\django\db\models\fields\related_lookups.py", line 166, in get_prep_lookup
    self.rhs = target_field.get_prep_value(self.rhs)
  File "C:\Users\fabro\AppData\Local\Programs\Python\Python310\lib\site-packages\django\db\models\fields\__init__.py", line 2020, in get_prep_value
    raise e.__class__(
TypeError: Field 'id' expected a number but got <SimpleLazyObject: <django.contrib.auth.models.AnonymousUser object at 0x00000253F9C418A0>>.
2022-11-12 09:59:10,248 Internal Server Error: /one_event/4
Traceback (most recent call last):
  File "C:\Users\fabro\AppData\Local\Programs\Python\Python310\lib\site-packages\django\db\models\fields\__init__.py", line 2018, in get_prep_value
    return int(value)
TypeError: int() argument must be a string, a bytes-like object or a real number, not 'SimpleLazyObject'

The above exception was the direct cause of the following exception:

Traceback (most recent call last):
  File "C:\Users\fabro\AppData\Local\Programs\Python\Python310\lib\site-packages\django\core\handlers\exception.py", line 55, in inner
    response = get_response(request)
  File "C:\Users\fabro\AppData\Local\Programs\Python\Python310\lib\site-packages\django\core\handlers\base.py", line 197, in _get_response
    response = wrapped_callback(request, *callback_args, **callback_kwargs)
  File "C:\PythonRemoteCZ7\Event_App\base\views.py", line 31, in event_detail
    latest_response = EventResponse.objects.filter(
  File "C:\Users\fabro\AppData\Local\Programs\Python\Python310\lib\site-packages\django\db\models\manager.py", line 85, in manager_method
    return getattr(self.get_queryset(), name)(*args, **kwargs)
  File "C:\Users\fabro\AppData\Local\Programs\Python\Python310\lib\site-packages\django\db\models\query.py", line 1420, in filter
    return self._filter_or_exclude(False, args, kwargs)
  File "C:\Users\fabro\AppData\Local\Programs\Python\Python310\lib\site-packages\django\db\models\query.py", line 1438, in _filter_or_exclude
    clone._filter_or_exclude_inplace(negate, args, kwargs)
  File "C:\Users\fabro\AppData\Local\Programs\Python\Python310\lib\site-packages\django\db\models\query.py", line 1445, in _filter_or_exclude_inplace
    self._query.add_q(Q(*args, **kwargs))
  File "C:\Users\fabro\AppData\Local\Programs\Python\Python310\lib\site-packages\django\db\models\sql\query.py", line 1532, in add_q
    clause, _ = self._add_q(q_object, self.used_aliases)
  File "C:\Users\fabro\AppData\Local\Programs\Python\Python310\lib\site-packages\django\db\models\sql\query.py", line 1562, in _add_q
    child_clause, needed_inner = self.build_filter(
  File "C:\Users\fabro\AppData\Local\Programs\Python\Python310\lib\site-packages\django\db\models\sql\query.py", line 1478, in build_filter
    condition = self.build_lookup(lookups, col, value)
  File "C:\Users\fabro\AppData\Local\Programs\Python\Python310\lib\site-packages\django\db\models\sql\query.py", line 1303, in build_lookup
    lookup = lookup_class(lhs, rhs)
  File "C:\Users\fabro\AppData\Local\Programs\Python\Python310\lib\site-packages\django\db\models\lookups.py", line 27, in __init__
    self.rhs = self.get_prep_lookup()
  File "C:\Users\fabro\AppData\Local\Programs\Python\Python310\lib\site-packages\django\db\models\fields\related_lookups.py", line 166, in get_prep_lookup
    self.rhs = target_field.get_prep_value(self.rhs)
  File "C:\Users\fabro\AppData\Local\Programs\Python\Python310\lib\site-packages\django\db\models\fields\__init__.py", line 2020, in get_prep_value
    raise e.__class__(
TypeError: Field 'id' expected a number but got <SimpleLazyObject: <django.contrib.auth.models.AnonymousUser object at 0x00000253F9BFAB00>>.
2022-11-12 09:59:11,764 Internal Server Error: /one_event/4
Traceback (most recent call last):
  File "C:\Users\fabro\AppData\Local\Programs\Python\Python310\lib\site-packages\django\db\models\fields\__init__.py", line 2018, in get_prep_value
    return int(value)
TypeError: int() argument must be a string, a bytes-like object or a real number, not 'SimpleLazyObject'

The above exception was the direct cause of the following exception:

Traceback (most recent call last):
  File "C:\Users\fabro\AppData\Local\Programs\Python\Python310\lib\site-packages\django\core\handlers\exception.py", line 55, in inner
    response = get_response(request)
  File "C:\Users\fabro\AppData\Local\Programs\Python\Python310\lib\site-packages\django\core\handlers\base.py", line 197, in _get_response
    response = wrapped_callback(request, *callback_args, **callback_kwargs)
  File "C:\PythonRemoteCZ7\Event_App\base\views.py", line 31, in event_detail
    latest_response = EventResponse.objects.filter(
  File "C:\Users\fabro\AppData\Local\Programs\Python\Python310\lib\site-packages\django\db\models\manager.py", line 85, in manager_method
    return getattr(self.get_queryset(), name)(*args, **kwargs)
  File "C:\Users\fabro\AppData\Local\Programs\Python\Python310\lib\site-packages\django\db\models\query.py", line 1420, in filter
    return self._filter_or_exclude(False, args, kwargs)
  File "C:\Users\fabro\AppData\Local\Programs\Python\Python310\lib\site-packages\django\db\models\query.py", line 1438, in _filter_or_exclude
    clone._filter_or_exclude_inplace(negate, args, kwargs)
  File "C:\Users\fabro\AppData\Local\Programs\Python\Python310\lib\site-packages\django\db\models\query.py", line 1445, in _filter_or_exclude_inplace
    self._query.add_q(Q(*args, **kwargs))
  File "C:\Users\fabro\AppData\Local\Programs\Python\Python310\lib\site-packages\django\db\models\sql\query.py", line 1532, in add_q
    clause, _ = self._add_q(q_object, self.used_aliases)
  File "C:\Users\fabro\AppData\Local\Programs\Python\Python310\lib\site-packages\django\db\models\sql\query.py", line 1562, in _add_q
    child_clause, needed_inner = self.build_filter(
  File "C:\Users\fabro\AppData\Local\Programs\Python\Python310\lib\site-packages\django\db\models\sql\query.py", line 1478, in build_filter
    condition = self.build_lookup(lookups, col, value)
  File "C:\Users\fabro\AppData\Local\Programs\Python\Python310\lib\site-packages\django\db\models\sql\query.py", line 1303, in build_lookup
    lookup = lookup_class(lhs, rhs)
  File "C:\Users\fabro\AppData\Local\Programs\Python\Python310\lib\site-packages\django\db\models\lookups.py", line 27, in __init__
    self.rhs = self.get_prep_lookup()
  File "C:\Users\fabro\AppData\Local\Programs\Python\Python310\lib\site-packages\django\db\models\fields\related_lookups.py", line 166, in get_prep_lookup
    self.rhs = target_field.get_prep_value(self.rhs)
  File "C:\Users\fabro\AppData\Local\Programs\Python\Python310\lib\site-packages\django\db\models\fields\__init__.py", line 2020, in get_prep_value
    raise e.__class__(
TypeError: Field 'id' expected a number but got <SimpleLazyObject: <django.contrib.auth.models.AnonymousUser object at 0x00000253F9C43BE0>>.
2022-11-12 09:59:12,076 Internal Server Error: /one_event/4
Traceback (most recent call last):
  File "C:\Users\fabro\AppData\Local\Programs\Python\Python310\lib\site-packages\django\db\models\fields\__init__.py", line 2018, in get_prep_value
    return int(value)
TypeError: int() argument must be a string, a bytes-like object or a real number, not 'SimpleLazyObject'

The above exception was the direct cause of the following exception:

Traceback (most recent call last):
  File "C:\Users\fabro\AppData\Local\Programs\Python\Python310\lib\site-packages\django\core\handlers\exception.py", line 55, in inner
    response = get_response(request)
  File "C:\Users\fabro\AppData\Local\Programs\Python\Python310\lib\site-packages\django\core\handlers\base.py", line 197, in _get_response
    response = wrapped_callback(request, *callback_args, **callback_kwargs)
  File "C:\PythonRemoteCZ7\Event_App\base\views.py", line 31, in event_detail
    latest_response = EventResponse.objects.filter(
  File "C:\Users\fabro\AppData\Local\Programs\Python\Python310\lib\site-packages\django\db\models\manager.py", line 85, in manager_method
    return getattr(self.get_queryset(), name)(*args, **kwargs)
  File "C:\Users\fabro\AppData\Local\Programs\Python\Python310\lib\site-packages\django\db\models\query.py", line 1420, in filter
    return self._filter_or_exclude(False, args, kwargs)
  File "C:\Users\fabro\AppData\Local\Programs\Python\Python310\lib\site-packages\django\db\models\query.py", line 1438, in _filter_or_exclude
    clone._filter_or_exclude_inplace(negate, args, kwargs)
  File "C:\Users\fabro\AppData\Local\Programs\Python\Python310\lib\site-packages\django\db\models\query.py", line 1445, in _filter_or_exclude_inplace
    self._query.add_q(Q(*args, **kwargs))
  File "C:\Users\fabro\AppData\Local\Programs\Python\Python310\lib\site-packages\django\db\models\sql\query.py", line 1532, in add_q
    clause, _ = self._add_q(q_object, self.used_aliases)
  File "C:\Users\fabro\AppData\Local\Programs\Python\Python310\lib\site-packages\django\db\models\sql\query.py", line 1562, in _add_q
    child_clause, needed_inner = self.build_filter(
  File "C:\Users\fabro\AppData\Local\Programs\Python\Python310\lib\site-packages\django\db\models\sql\query.py", line 1478, in build_filter
    condition = self.build_lookup(lookups, col, value)
  File "C:\Users\fabro\AppData\Local\Programs\Python\Python310\lib\site-packages\django\db\models\sql\query.py", line 1303, in build_lookup
    lookup = lookup_class(lhs, rhs)
  File "C:\Users\fabro\AppData\Local\Programs\Python\Python310\lib\site-packages\django\db\models\lookups.py", line 27, in __init__
    self.rhs = self.get_prep_lookup()
  File "C:\Users\fabro\AppData\Local\Programs\Python\Python310\lib\site-packages\django\db\models\fields\related_lookups.py", line 166, in get_prep_lookup
    self.rhs = target_field.get_prep_value(self.rhs)
  File "C:\Users\fabro\AppData\Local\Programs\Python\Python310\lib\site-packages\django\db\models\fields\__init__.py", line 2020, in get_prep_value
    raise e.__class__(
TypeError: Field 'id' expected a number but got <SimpleLazyObject: <django.contrib.auth.models.AnonymousUser object at 0x00000253FA6F25F0>>.
2022-11-12 09:59:19,577 Internal Server Error: /one_event/3
Traceback (most recent call last):
  File "C:\Users\fabro\AppData\Local\Programs\Python\Python310\lib\site-packages\django\db\models\fields\__init__.py", line 2018, in get_prep_value
    return int(value)
TypeError: int() argument must be a string, a bytes-like object or a real number, not 'SimpleLazyObject'

The above exception was the direct cause of the following exception:

Traceback (most recent call last):
  File "C:\Users\fabro\AppData\Local\Programs\Python\Python310\lib\site-packages\django\core\handlers\exception.py", line 55, in inner
    response = get_response(request)
  File "C:\Users\fabro\AppData\Local\Programs\Python\Python310\lib\site-packages\django\core\handlers\base.py", line 197, in _get_response
    response = wrapped_callback(request, *callback_args, **callback_kwargs)
  File "C:\PythonRemoteCZ7\Event_App\base\views.py", line 31, in event_detail
    latest_response = EventResponse.objects.filter(
  File "C:\Users\fabro\AppData\Local\Programs\Python\Python310\lib\site-packages\django\db\models\manager.py", line 85, in manager_method
    return getattr(self.get_queryset(), name)(*args, **kwargs)
  File "C:\Users\fabro\AppData\Local\Programs\Python\Python310\lib\site-packages\django\db\models\query.py", line 1420, in filter
    return self._filter_or_exclude(False, args, kwargs)
  File "C:\Users\fabro\AppData\Local\Programs\Python\Python310\lib\site-packages\django\db\models\query.py", line 1438, in _filter_or_exclude
    clone._filter_or_exclude_inplace(negate, args, kwargs)
  File "C:\Users\fabro\AppData\Local\Programs\Python\Python310\lib\site-packages\django\db\models\query.py", line 1445, in _filter_or_exclude_inplace
    self._query.add_q(Q(*args, **kwargs))
  File "C:\Users\fabro\AppData\Local\Programs\Python\Python310\lib\site-packages\django\db\models\sql\query.py", line 1532, in add_q
    clause, _ = self._add_q(q_object, self.used_aliases)
  File "C:\Users\fabro\AppData\Local\Programs\Python\Python310\lib\site-packages\django\db\models\sql\query.py", line 1562, in _add_q
    child_clause, needed_inner = self.build_filter(
  File "C:\Users\fabro\AppData\Local\Programs\Python\Python310\lib\site-packages\django\db\models\sql\query.py", line 1478, in build_filter
    condition = self.build_lookup(lookups, col, value)
  File "C:\Users\fabro\AppData\Local\Programs\Python\Python310\lib\site-packages\django\db\models\sql\query.py", line 1303, in build_lookup
    lookup = lookup_class(lhs, rhs)
  File "C:\Users\fabro\AppData\Local\Programs\Python\Python310\lib\site-packages\django\db\models\lookups.py", line 27, in __init__
    self.rhs = self.get_prep_lookup()
  File "C:\Users\fabro\AppData\Local\Programs\Python\Python310\lib\site-packages\django\db\models\fields\related_lookups.py", line 166, in get_prep_lookup
    self.rhs = target_field.get_prep_value(self.rhs)
  File "C:\Users\fabro\AppData\Local\Programs\Python\Python310\lib\site-packages\django\db\models\fields\__init__.py", line 2020, in get_prep_value
    raise e.__class__(
TypeError: Field 'id' expected a number but got <SimpleLazyObject: <django.contrib.auth.models.AnonymousUser object at 0x00000253F9B55FC0>>.
2022-11-12 10:46:14,476 Internal Server Error: /admin/base/event/add/
Traceback (most recent call last):
  File "C:\Users\fabro\AppData\Local\Programs\Python\Python310\lib\site-packages\django\db\backends\utils.py", line 89, in _execute
    return self.cursor.execute(sql, params)
  File "C:\Users\fabro\AppData\Local\Programs\Python\Python310\lib\site-packages\django\db\backends\sqlite3\base.py", line 357, in execute
    return Database.Cursor.execute(self, query, params)
sqlite3.IntegrityError: NOT NULL constraint failed: base_event.date_active

The above exception was the direct cause of the following exception:

Traceback (most recent call last):
  File "C:\Users\fabro\AppData\Local\Programs\Python\Python310\lib\site-packages\django\core\handlers\exception.py", line 55, in inner
    response = get_response(request)
  File "C:\Users\fabro\AppData\Local\Programs\Python\Python310\lib\site-packages\django\core\handlers\base.py", line 197, in _get_response
    response = wrapped_callback(request, *callback_args, **callback_kwargs)
  File "C:\Users\fabro\AppData\Local\Programs\Python\Python310\lib\site-packages\django\contrib\admin\options.py", line 686, in wrapper
    return self.admin_site.admin_view(view)(*args, **kwargs)
  File "C:\Users\fabro\AppData\Local\Programs\Python\Python310\lib\site-packages\django\utils\decorators.py", line 133, in _wrapped_view
    response = view_func(request, *args, **kwargs)
  File "C:\Users\fabro\AppData\Local\Programs\Python\Python310\lib\site-packages\django\views\decorators\cache.py", line 62, in _wrapped_view_func
    response = view_func(request, *args, **kwargs)
  File "C:\Users\fabro\AppData\Local\Programs\Python\Python310\lib\site-packages\django\contrib\admin\sites.py", line 242, in inner
    return view(request, *args, **kwargs)
  File "C:\Users\fabro\AppData\Local\Programs\Python\Python310\lib\site-packages\django\contrib\admin\options.py", line 1890, in add_view
    return self.changeform_view(request, None, form_url, extra_context)
  File "C:\Users\fabro\AppData\Local\Programs\Python\Python310\lib\site-packages\django\utils\decorators.py", line 46, in _wrapper
    return bound_method(*args, **kwargs)
  File "C:\Users\fabro\AppData\Local\Programs\Python\Python310\lib\site-packages\django\utils\decorators.py", line 133, in _wrapped_view
    response = view_func(request, *args, **kwargs)
  File "C:\Users\fabro\AppData\Local\Programs\Python\Python310\lib\site-packages\django\contrib\admin\options.py", line 1750, in changeform_view
    return self._changeform_view(request, object_id, form_url, extra_context)
  File "C:\Users\fabro\AppData\Local\Programs\Python\Python310\lib\site-packages\django\contrib\admin\options.py", line 1802, in _changeform_view
    self.save_model(request, new_object, form, not add)
  File "C:\Users\fabro\AppData\Local\Programs\Python\Python310\lib\site-packages\django\contrib\admin\options.py", line 1225, in save_model
    obj.save()
  File "C:\Users\fabro\AppData\Local\Programs\Python\Python310\lib\site-packages\django\db\models\base.py", line 831, in save
    self.save_base(
  File "C:\Users\fabro\AppData\Local\Programs\Python\Python310\lib\site-packages\django\db\models\base.py", line 882, in save_base
    updated = self._save_table(
  File "C:\Users\fabro\AppData\Local\Programs\Python\Python310\lib\site-packages\django\db\models\base.py", line 1025, in _save_table
    results = self._do_insert(
  File "C:\Users\fabro\AppData\Local\Programs\Python\Python310\lib\site-packages\django\db\models\base.py", line 1066, in _do_insert
    return manager._insert(
  File "C:\Users\fabro\AppData\Local\Programs\Python\Python310\lib\site-packages\django\db\models\manager.py", line 85, in manager_method
    return getattr(self.get_queryset(), name)(*args, **kwargs)
  File "C:\Users\fabro\AppData\Local\Programs\Python\Python310\lib\site-packages\django\db\models\query.py", line 1790, in _insert
    return query.get_compiler(using=using).execute_sql(returning_fields)
  File "C:\Users\fabro\AppData\Local\Programs\Python\Python310\lib\site-packages\django\db\models\sql\compiler.py", line 1657, in execute_sql
    cursor.execute(sql, params)
  File "C:\Users\fabro\AppData\Local\Programs\Python\Python310\lib\site-packages\django\db\backends\utils.py", line 103, in execute
    return super().execute(sql, params)
  File "C:\Users\fabro\AppData\Local\Programs\Python\Python310\lib\site-packages\django\db\backends\utils.py", line 67, in execute
    return self._execute_with_wrappers(
  File "C:\Users\fabro\AppData\Local\Programs\Python\Python310\lib\site-packages\django\db\backends\utils.py", line 80, in _execute_with_wrappers
    return executor(sql, params, many, context)
  File "C:\Users\fabro\AppData\Local\Programs\Python\Python310\lib\site-packages\django\db\backends\utils.py", line 84, in _execute
    with self.db.wrap_database_errors:
  File "C:\Users\fabro\AppData\Local\Programs\Python\Python310\lib\site-packages\django\db\utils.py", line 91, in __exit__
    raise dj_exc_value.with_traceback(traceback) from exc_value
  File "C:\Users\fabro\AppData\Local\Programs\Python\Python310\lib\site-packages\django\db\backends\utils.py", line 89, in _execute
    return self.cursor.execute(sql, params)
  File "C:\Users\fabro\AppData\Local\Programs\Python\Python310\lib\site-packages\django\db\backends\sqlite3\base.py", line 357, in execute
    return Database.Cursor.execute(self, query, params)
django.db.utils.IntegrityError: NOT NULL constraint failed: base_event.date_active
2022-11-12 11:03:12,207 User id 1 responded yes to event id 6.
2022-11-12 11:14:42,477 Not Found: /favicon.ico
2022-11-12 11:15:56,458 Not Found: /favicon.ico
2022-11-12 11:18:48,312 Not Found: /favicon.ico
2022-11-12 11:21:11,409 Not Found: /favicon.ico
2022-11-12 11:55:18,882 C:\PythonRemoteCZ7\Event_App\base\views.py changed, reloading.
2022-11-12 11:56:30,517 C:\PythonRemoteCZ7\Event_App\base\views.py changed, reloading.
2022-11-12 12:25:40,665 Not Found: /favicon.ico
2022-11-12 12:29:56,825 User id 1 responded no to event id 6.
2022-11-12 12:43:32,706 Internal Server Error: /search/
Traceback (most recent call last):
  File "C:\Users\fabro\AppData\Local\Programs\Python\Python310\lib\site-packages\django\template\smartif.py", line 179, in translate_token
    op = OPERATORS[token]
KeyError: 'bool(q)'

During handling of the above exception, another exception occurred:

Traceback (most recent call last):
  File "C:\Users\fabro\AppData\Local\Programs\Python\Python310\lib\site-packages\django\core\handlers\exception.py", line 55, in inner
    response = get_response(request)
  File "C:\Users\fabro\AppData\Local\Programs\Python\Python310\lib\site-packages\django\core\handlers\base.py", line 197, in _get_response
    response = wrapped_callback(request, *callback_args, **callback_kwargs)
  File "C:\PythonRemoteCZ7\Event_App\base\views.py", line 71, in event_search
    return render(request, "base/search.html", context)
  File "C:\Users\fabro\AppData\Local\Programs\Python\Python310\lib\site-packages\django\shortcuts.py", line 24, in render
    content = loader.render_to_string(template_name, context, request, using=using)
  File "C:\Users\fabro\AppData\Local\Programs\Python\Python310\lib\site-packages\django\template\loader.py", line 61, in render_to_string
    template = get_template(template_name, using=using)
  File "C:\Users\fabro\AppData\Local\Programs\Python\Python310\lib\site-packages\django\template\loader.py", line 15, in get_template
    return engine.get_template(template_name)
  File "C:\Users\fabro\AppData\Local\Programs\Python\Python310\lib\site-packages\django\template\backends\django.py", line 34, in get_template
    return Template(self.engine.get_template(template_name), self)
  File "C:\Users\fabro\AppData\Local\Programs\Python\Python310\lib\site-packages\django\template\engine.py", line 175, in get_template
    template, origin = self.find_template(template_name)
  File "C:\Users\fabro\AppData\Local\Programs\Python\Python310\lib\site-packages\django\template\engine.py", line 157, in find_template
    template = loader.get_template(name, skip=skip)
  File "C:\Users\fabro\AppData\Local\Programs\Python\Python310\lib\site-packages\django\template\loaders\cached.py", line 57, in get_template
    template = super().get_template(template_name, skip)
  File "C:\Users\fabro\AppData\Local\Programs\Python\Python310\lib\site-packages\django\template\loaders\base.py", line 28, in get_template
    return Template(
  File "C:\Users\fabro\AppData\Local\Programs\Python\Python310\lib\site-packages\django\template\base.py", line 154, in __init__
    self.nodelist = self.compile_nodelist()
  File "C:\Users\fabro\AppData\Local\Programs\Python\Python310\lib\site-packages\django\template\base.py", line 200, in compile_nodelist
    return parser.parse()
  File "C:\Users\fabro\AppData\Local\Programs\Python\Python310\lib\site-packages\django\template\base.py", line 513, in parse
    raise self.error(token, e)
  File "C:\Users\fabro\AppData\Local\Programs\Python\Python310\lib\site-packages\django\template\base.py", line 511, in parse
    compiled_result = compile_func(self, token)
  File "C:\Users\fabro\AppData\Local\Programs\Python\Python310\lib\site-packages\django\template\loader_tags.py", line 293, in do_extends
    nodelist = parser.parse()
  File "C:\Users\fabro\AppData\Local\Programs\Python\Python310\lib\site-packages\django\template\base.py", line 513, in parse
    raise self.error(token, e)
  File "C:\Users\fabro\AppData\Local\Programs\Python\Python310\lib\site-packages\django\template\base.py", line 511, in parse
    compiled_result = compile_func(self, token)
  File "C:\Users\fabro\AppData\Local\Programs\Python\Python310\lib\site-packages\django\template\loader_tags.py", line 232, in do_block
    nodelist = parser.parse(("endblock",))
  File "C:\Users\fabro\AppData\Local\Programs\Python\Python310\lib\site-packages\django\template\base.py", line 513, in parse
    raise self.error(token, e)
  File "C:\Users\fabro\AppData\Local\Programs\Python\Python310\lib\site-packages\django\template\base.py", line 511, in parse
    compiled_result = compile_func(self, token)
  File "C:\Users\fabro\AppData\Local\Programs\Python\Python310\lib\site-packages\django\template\defaulttags.py", line 953, in do_if
    condition = TemplateIfParser(parser, bits).parse()
  File "C:\Users\fabro\AppData\Local\Programs\Python\Python310\lib\site-packages\django\template\defaulttags.py", line 886, in __init__
    super().__init__(*args, **kwargs)
  File "C:\Users\fabro\AppData\Local\Programs\Python\Python310\lib\site-packages\django\template\smartif.py", line 170, in __init__
    mapped_tokens.append(self.translate_token(token))
  File "C:\Users\fabro\AppData\Local\Programs\Python\Python310\lib\site-packages\django\template\smartif.py", line 181, in translate_token
    return self.create_var(token)
  File "C:\Users\fabro\AppData\Local\Programs\Python\Python310\lib\site-packages\django\template\defaulttags.py", line 889, in create_var
    return TemplateLiteral(self.template_parser.compile_filter(value), value)
  File "C:\Users\fabro\AppData\Local\Programs\Python\Python310\lib\site-packages\django\template\base.py", line 600, in compile_filter
    return FilterExpression(token, self)
  File "C:\Users\fabro\AppData\Local\Programs\Python\Python310\lib\site-packages\django\template\base.py", line 703, in __init__
    raise TemplateSyntaxError(
django.template.exceptions.TemplateSyntaxError: Could not parse the remainder: '(q)' from 'bool(q)'
2022-11-12 12:48:03,524 C:\PythonRemoteCZ7\Event_App\base\views.py changed, reloading.
2022-11-12 12:59:01,977 Not Found: /favicon.ico
2022-11-12 13:02:35,307 Not Found: /favicon.ico
2022-11-12 13:11:38,572 Not Found: /favicon.ico
2022-11-12 14:06:07,395 User id 1 responded yes to event id 6.
2022-11-12 14:08:56,027 C:\PythonRemoteCZ7\Event_App\base\forms.py changed, reloading.
2022-11-12 14:21:40,492 Not Found: /favicon.ico
2022-11-12 14:55:52,168 Internal Server Error: /one_event/6
Traceback (most recent call last):
  File "C:\Users\fabro\AppData\Local\Programs\Python\Python310\lib\site-packages\django\core\handlers\exception.py", line 55, in inner
    response = get_response(request)
  File "C:\Users\fabro\AppData\Local\Programs\Python\Python310\lib\site-packages\django\core\handlers\base.py", line 197, in _get_response
    response = wrapped_callback(request, *callback_args, **callback_kwargs)
  File "C:\PythonRemoteCZ7\Event_App\base\views.py", line 49, in event_detail
    return render(request, 'base/one_event.html', context)
  File "C:\Users\fabro\AppData\Local\Programs\Python\Python310\lib\site-packages\django\shortcuts.py", line 24, in render
    content = loader.render_to_string(template_name, context, request, using=using)
  File "C:\Users\fabro\AppData\Local\Programs\Python\Python310\lib\site-packages\django\template\loader.py", line 62, in render_to_string
    return template.render(context, request)
  File "C:\Users\fabro\AppData\Local\Programs\Python\Python310\lib\site-packages\django\template\backends\django.py", line 62, in render
    return self.template.render(context)
  File "C:\Users\fabro\AppData\Local\Programs\Python\Python310\lib\site-packages\django\template\base.py", line 175, in render
    return self._render(context)
  File "C:\Users\fabro\AppData\Local\Programs\Python\Python310\lib\site-packages\django\template\base.py", line 167, in _render
    return self.nodelist.render(context)
  File "C:\Users\fabro\AppData\Local\Programs\Python\Python310\lib\site-packages\django\template\base.py", line 1005, in render
    return SafeString("".join([node.render_annotated(context) for node in self]))
  File "C:\Users\fabro\AppData\Local\Programs\Python\Python310\lib\site-packages\django\template\base.py", line 1005, in <listcomp>
    return SafeString("".join([node.render_annotated(context) for node in self]))
  File "C:\Users\fabro\AppData\Local\Programs\Python\Python310\lib\site-packages\django\template\base.py", line 966, in render_annotated
    return self.render(context)
  File "C:\Users\fabro\AppData\Local\Programs\Python\Python310\lib\site-packages\django\template\loader_tags.py", line 157, in render
    return compiled_parent._render(context)
  File "C:\Users\fabro\AppData\Local\Programs\Python\Python310\lib\site-packages\django\template\base.py", line 167, in _render
    return self.nodelist.render(context)
  File "C:\Users\fabro\AppData\Local\Programs\Python\Python310\lib\site-packages\django\template\base.py", line 1005, in render
    return SafeString("".join([node.render_annotated(context) for node in self]))
  File "C:\Users\fabro\AppData\Local\Programs\Python\Python310\lib\site-packages\django\template\base.py", line 1005, in <listcomp>
    return SafeString("".join([node.render_annotated(context) for node in self]))
  File "C:\Users\fabro\AppData\Local\Programs\Python\Python310\lib\site-packages\django\template\base.py", line 966, in render_annotated
    return self.render(context)
  File "C:\Users\fabro\AppData\Local\Programs\Python\Python310\lib\site-packages\django\template\loader_tags.py", line 63, in render
    result = block.nodelist.render(context)
  File "C:\Users\fabro\AppData\Local\Programs\Python\Python310\lib\site-packages\django\template\base.py", line 1005, in render
    return SafeString("".join([node.render_annotated(context) for node in self]))
  File "C:\Users\fabro\AppData\Local\Programs\Python\Python310\lib\site-packages\django\template\base.py", line 1005, in <listcomp>
    return SafeString("".join([node.render_annotated(context) for node in self]))
  File "C:\Users\fabro\AppData\Local\Programs\Python\Python310\lib\site-packages\django\template\base.py", line 966, in render_annotated
    return self.render(context)
  File "C:\Users\fabro\AppData\Local\Programs\Python\Python310\lib\site-packages\django\template\defaulttags.py", line 322, in render
    return nodelist.render(context)
  File "C:\Users\fabro\AppData\Local\Programs\Python\Python310\lib\site-packages\django\template\base.py", line 1005, in render
    return SafeString("".join([node.render_annotated(context) for node in self]))
  File "C:\Users\fabro\AppData\Local\Programs\Python\Python310\lib\site-packages\django\template\base.py", line 1005, in <listcomp>
    return SafeString("".join([node.render_annotated(context) for node in self]))
  File "C:\Users\fabro\AppData\Local\Programs\Python\Python310\lib\site-packages\django\template\base.py", line 966, in render_annotated
    return self.render(context)
  File "C:\Users\fabro\AppData\Local\Programs\Python\Python310\lib\site-packages\django\template\defaulttags.py", line 472, in render
    url = reverse(view_name, args=args, kwargs=kwargs, current_app=current_app)
  File "C:\Users\fabro\AppData\Local\Programs\Python\Python310\lib\site-packages\django\urls\base.py", line 88, in reverse
    return resolver._reverse_with_prefix(view, prefix, *args, **kwargs)
  File "C:\Users\fabro\AppData\Local\Programs\Python\Python310\lib\site-packages\django\urls\resolvers.py", line 828, in _reverse_with_prefix
    raise NoReverseMatch(msg)
django.urls.exceptions.NoReverseMatch: Reverse for 'response' with arguments '('',)' not found. 1 pattern(s) tried: ['response/(?P<pk>[^/]+)\\Z']
2022-11-12 14:57:58,705 User id 1 responded no to event id 6.
2022-11-12 14:58:11,113 User id 1 responded yes to event id 6.
2022-11-12 14:58:15,551 User id 1 responded no to event id 6.
2022-11-12 14:58:25,640 User id 1 responded maybe to event id 6.
2022-11-12 15:00:26,319 C:\PythonRemoteCZ7\Event_App\EventApp\urls.py changed, reloading.
2022-11-12 15:09:36,375 C:\PythonRemoteCZ7\Event_App\EventApp\urls.py changed, reloading.
2022-11-12 15:12:27,414 C:\PythonRemoteCZ7\Event_App\user\views.py changed, reloading.
2022-11-12 15:16:07,324 Not Found: /login
2022-11-12 15:20:49,403 C:\PythonRemoteCZ7\Event_App\EventApp\urls.py changed, reloading.
2022-11-12 15:22:32,647 Not Found: /prihlasit/
2022-11-12 15:22:47,864 Internal Server Error: /
Traceback (most recent call last):
  File "C:\Users\fabro\AppData\Local\Programs\Python\Python310\lib\site-packages\django\core\handlers\exception.py", line 55, in inner
    response = get_response(request)
  File "C:\Users\fabro\AppData\Local\Programs\Python\Python310\lib\site-packages\django\core\handlers\base.py", line 220, in _get_response
    response = response.render()
  File "C:\Users\fabro\AppData\Local\Programs\Python\Python310\lib\site-packages\django\template\response.py", line 114, in render
    self.content = self.rendered_content
  File "C:\Users\fabro\AppData\Local\Programs\Python\Python310\lib\site-packages\django\template\response.py", line 92, in rendered_content
    return template.render(context, self._request)
  File "C:\Users\fabro\AppData\Local\Programs\Python\Python310\lib\site-packages\django\template\backends\django.py", line 62, in render
    return self.template.render(context)
  File "C:\Users\fabro\AppData\Local\Programs\Python\Python310\lib\site-packages\django\template\base.py", line 175, in render
    return self._render(context)
  File "C:\Users\fabro\AppData\Local\Programs\Python\Python310\lib\site-packages\django\template\base.py", line 167, in _render
    return self.nodelist.render(context)
  File "C:\Users\fabro\AppData\Local\Programs\Python\Python310\lib\site-packages\django\template\base.py", line 1005, in render
    return SafeString("".join([node.render_annotated(context) for node in self]))
  File "C:\Users\fabro\AppData\Local\Programs\Python\Python310\lib\site-packages\django\template\base.py", line 1005, in <listcomp>
    return SafeString("".join([node.render_annotated(context) for node in self]))
  File "C:\Users\fabro\AppData\Local\Programs\Python\Python310\lib\site-packages\django\template\base.py", line 966, in render_annotated
    return self.render(context)
  File "C:\Users\fabro\AppData\Local\Programs\Python\Python310\lib\site-packages\django\template\loader_tags.py", line 157, in render
    return compiled_parent._render(context)
  File "C:\Users\fabro\AppData\Local\Programs\Python\Python310\lib\site-packages\django\template\base.py", line 167, in _render
    return self.nodelist.render(context)
  File "C:\Users\fabro\AppData\Local\Programs\Python\Python310\lib\site-packages\django\template\base.py", line 1005, in render
    return SafeString("".join([node.render_annotated(context) for node in self]))
  File "C:\Users\fabro\AppData\Local\Programs\Python\Python310\lib\site-packages\django\template\base.py", line 1005, in <listcomp>
    return SafeString("".join([node.render_annotated(context) for node in self]))
  File "C:\Users\fabro\AppData\Local\Programs\Python\Python310\lib\site-packages\django\template\base.py", line 966, in render_annotated
    return self.render(context)
  File "C:\Users\fabro\AppData\Local\Programs\Python\Python310\lib\site-packages\django\template\loader_tags.py", line 208, in render
    return template.render(context)
  File "C:\Users\fabro\AppData\Local\Programs\Python\Python310\lib\site-packages\django\template\base.py", line 177, in render
    return self._render(context)
  File "C:\Users\fabro\AppData\Local\Programs\Python\Python310\lib\site-packages\django\template\base.py", line 167, in _render
    return self.nodelist.render(context)
  File "C:\Users\fabro\AppData\Local\Programs\Python\Python310\lib\site-packages\django\template\base.py", line 1005, in render
    return SafeString("".join([node.render_annotated(context) for node in self]))
  File "C:\Users\fabro\AppData\Local\Programs\Python\Python310\lib\site-packages\django\template\base.py", line 1005, in <listcomp>
    return SafeString("".join([node.render_annotated(context) for node in self]))
  File "C:\Users\fabro\AppData\Local\Programs\Python\Python310\lib\site-packages\django\template\base.py", line 966, in render_annotated
    return self.render(context)
  File "C:\Users\fabro\AppData\Local\Programs\Python\Python310\lib\site-packages\django\template\defaulttags.py", line 472, in render
    url = reverse(view_name, args=args, kwargs=kwargs, current_app=current_app)
  File "C:\Users\fabro\AppData\Local\Programs\Python\Python310\lib\site-packages\django\urls\base.py", line 88, in reverse
    return resolver._reverse_with_prefix(view, prefix, *args, **kwargs)
  File "C:\Users\fabro\AppData\Local\Programs\Python\Python310\lib\site-packages\django\urls\resolvers.py", line 828, in _reverse_with_prefix
    raise NoReverseMatch(msg)
django.urls.exceptions.NoReverseMatch: Reverse for '' not found. '' is not a valid view function or pattern name.
2022-11-12 15:27:25,699 Internal Server Error: /
Traceback (most recent call last):
  File "C:\Users\fabro\AppData\Local\Programs\Python\Python310\lib\site-packages\django\core\handlers\exception.py", line 55, in inner
    response = get_response(request)
  File "C:\Users\fabro\AppData\Local\Programs\Python\Python310\lib\site-packages\django\core\handlers\base.py", line 220, in _get_response
    response = response.render()
  File "C:\Users\fabro\AppData\Local\Programs\Python\Python310\lib\site-packages\django\template\response.py", line 114, in render
    self.content = self.rendered_content
  File "C:\Users\fabro\AppData\Local\Programs\Python\Python310\lib\site-packages\django\template\response.py", line 92, in rendered_content
    return template.render(context, self._request)
  File "C:\Users\fabro\AppData\Local\Programs\Python\Python310\lib\site-packages\django\template\backends\django.py", line 62, in render
    return self.template.render(context)
  File "C:\Users\fabro\AppData\Local\Programs\Python\Python310\lib\site-packages\django\template\base.py", line 175, in render
    return self._render(context)
  File "C:\Users\fabro\AppData\Local\Programs\Python\Python310\lib\site-packages\django\template\base.py", line 167, in _render
    return self.nodelist.render(context)
  File "C:\Users\fabro\AppData\Local\Programs\Python\Python310\lib\site-packages\django\template\base.py", line 1005, in render
    return SafeString("".join([node.render_annotated(context) for node in self]))
  File "C:\Users\fabro\AppData\Local\Programs\Python\Python310\lib\site-packages\django\template\base.py", line 1005, in <listcomp>
    return SafeString("".join([node.render_annotated(context) for node in self]))
  File "C:\Users\fabro\AppData\Local\Programs\Python\Python310\lib\site-packages\django\template\base.py", line 966, in render_annotated
    return self.render(context)
  File "C:\Users\fabro\AppData\Local\Programs\Python\Python310\lib\site-packages\django\template\loader_tags.py", line 157, in render
    return compiled_parent._render(context)
  File "C:\Users\fabro\AppData\Local\Programs\Python\Python310\lib\site-packages\django\template\base.py", line 167, in _render
    return self.nodelist.render(context)
  File "C:\Users\fabro\AppData\Local\Programs\Python\Python310\lib\site-packages\django\template\base.py", line 1005, in render
    return SafeString("".join([node.render_annotated(context) for node in self]))
  File "C:\Users\fabro\AppData\Local\Programs\Python\Python310\lib\site-packages\django\template\base.py", line 1005, in <listcomp>
    return SafeString("".join([node.render_annotated(context) for node in self]))
  File "C:\Users\fabro\AppData\Local\Programs\Python\Python310\lib\site-packages\django\template\base.py", line 966, in render_annotated
    return self.render(context)
  File "C:\Users\fabro\AppData\Local\Programs\Python\Python310\lib\site-packages\django\template\loader_tags.py", line 208, in render
    return template.render(context)
  File "C:\Users\fabro\AppData\Local\Programs\Python\Python310\lib\site-packages\django\template\base.py", line 177, in render
    return self._render(context)
  File "C:\Users\fabro\AppData\Local\Programs\Python\Python310\lib\site-packages\django\template\base.py", line 167, in _render
    return self.nodelist.render(context)
  File "C:\Users\fabro\AppData\Local\Programs\Python\Python310\lib\site-packages\django\template\base.py", line 1005, in render
    return SafeString("".join([node.render_annotated(context) for node in self]))
  File "C:\Users\fabro\AppData\Local\Programs\Python\Python310\lib\site-packages\django\template\base.py", line 1005, in <listcomp>
    return SafeString("".join([node.render_annotated(context) for node in self]))
  File "C:\Users\fabro\AppData\Local\Programs\Python\Python310\lib\site-packages\django\template\base.py", line 966, in render_annotated
    return self.render(context)
  File "C:\Users\fabro\AppData\Local\Programs\Python\Python310\lib\site-packages\django\template\defaulttags.py", line 472, in render
    url = reverse(view_name, args=args, kwargs=kwargs, current_app=current_app)
  File "C:\Users\fabro\AppData\Local\Programs\Python\Python310\lib\site-packages\django\urls\base.py", line 88, in reverse
    return resolver._reverse_with_prefix(view, prefix, *args, **kwargs)
  File "C:\Users\fabro\AppData\Local\Programs\Python\Python310\lib\site-packages\django\urls\resolvers.py", line 828, in _reverse_with_prefix
    raise NoReverseMatch(msg)
django.urls.exceptions.NoReverseMatch: Reverse for 'Logout' not found. 'Logout' is not a valid view function or pattern name.
2022-11-12 15:27:28,465 Internal Server Error: /
Traceback (most recent call last):
  File "C:\Users\fabro\AppData\Local\Programs\Python\Python310\lib\site-packages\django\core\handlers\exception.py", line 55, in inner
    response = get_response(request)
  File "C:\Users\fabro\AppData\Local\Programs\Python\Python310\lib\site-packages\django\core\handlers\base.py", line 220, in _get_response
    response = response.render()
  File "C:\Users\fabro\AppData\Local\Programs\Python\Python310\lib\site-packages\django\template\response.py", line 114, in render
    self.content = self.rendered_content
  File "C:\Users\fabro\AppData\Local\Programs\Python\Python310\lib\site-packages\django\template\response.py", line 92, in rendered_content
    return template.render(context, self._request)
  File "C:\Users\fabro\AppData\Local\Programs\Python\Python310\lib\site-packages\django\template\backends\django.py", line 62, in render
    return self.template.render(context)
  File "C:\Users\fabro\AppData\Local\Programs\Python\Python310\lib\site-packages\django\template\base.py", line 175, in render
    return self._render(context)
  File "C:\Users\fabro\AppData\Local\Programs\Python\Python310\lib\site-packages\django\template\base.py", line 167, in _render
    return self.nodelist.render(context)
  File "C:\Users\fabro\AppData\Local\Programs\Python\Python310\lib\site-packages\django\template\base.py", line 1005, in render
    return SafeString("".join([node.render_annotated(context) for node in self]))
  File "C:\Users\fabro\AppData\Local\Programs\Python\Python310\lib\site-packages\django\template\base.py", line 1005, in <listcomp>
    return SafeString("".join([node.render_annotated(context) for node in self]))
  File "C:\Users\fabro\AppData\Local\Programs\Python\Python310\lib\site-packages\django\template\base.py", line 966, in render_annotated
    return self.render(context)
  File "C:\Users\fabro\AppData\Local\Programs\Python\Python310\lib\site-packages\django\template\loader_tags.py", line 157, in render
    return compiled_parent._render(context)
  File "C:\Users\fabro\AppData\Local\Programs\Python\Python310\lib\site-packages\django\template\base.py", line 167, in _render
    return self.nodelist.render(context)
  File "C:\Users\fabro\AppData\Local\Programs\Python\Python310\lib\site-packages\django\template\base.py", line 1005, in render
    return SafeString("".join([node.render_annotated(context) for node in self]))
  File "C:\Users\fabro\AppData\Local\Programs\Python\Python310\lib\site-packages\django\template\base.py", line 1005, in <listcomp>
    return SafeString("".join([node.render_annotated(context) for node in self]))
  File "C:\Users\fabro\AppData\Local\Programs\Python\Python310\lib\site-packages\django\template\base.py", line 966, in render_annotated
    return self.render(context)
  File "C:\Users\fabro\AppData\Local\Programs\Python\Python310\lib\site-packages\django\template\loader_tags.py", line 208, in render
    return template.render(context)
  File "C:\Users\fabro\AppData\Local\Programs\Python\Python310\lib\site-packages\django\template\base.py", line 177, in render
    return self._render(context)
  File "C:\Users\fabro\AppData\Local\Programs\Python\Python310\lib\site-packages\django\template\base.py", line 167, in _render
    return self.nodelist.render(context)
  File "C:\Users\fabro\AppData\Local\Programs\Python\Python310\lib\site-packages\django\template\base.py", line 1005, in render
    return SafeString("".join([node.render_annotated(context) for node in self]))
  File "C:\Users\fabro\AppData\Local\Programs\Python\Python310\lib\site-packages\django\template\base.py", line 1005, in <listcomp>
    return SafeString("".join([node.render_annotated(context) for node in self]))
  File "C:\Users\fabro\AppData\Local\Programs\Python\Python310\lib\site-packages\django\template\base.py", line 966, in render_annotated
    return self.render(context)
  File "C:\Users\fabro\AppData\Local\Programs\Python\Python310\lib\site-packages\django\template\defaulttags.py", line 472, in render
    url = reverse(view_name, args=args, kwargs=kwargs, current_app=current_app)
  File "C:\Users\fabro\AppData\Local\Programs\Python\Python310\lib\site-packages\django\urls\base.py", line 88, in reverse
    return resolver._reverse_with_prefix(view, prefix, *args, **kwargs)
  File "C:\Users\fabro\AppData\Local\Programs\Python\Python310\lib\site-packages\django\urls\resolvers.py", line 828, in _reverse_with_prefix
    raise NoReverseMatch(msg)
django.urls.exceptions.NoReverseMatch: Reverse for 'Logout' not found. 'Logout' is not a valid view function or pattern name.
2022-11-12 15:30:43,099 Internal Server Error: /
Traceback (most recent call last):
  File "C:\Users\fabro\AppData\Local\Programs\Python\Python310\lib\site-packages\django\core\handlers\exception.py", line 55, in inner
    response = get_response(request)
  File "C:\Users\fabro\AppData\Local\Programs\Python\Python310\lib\site-packages\django\core\handlers\base.py", line 220, in _get_response
    response = response.render()
  File "C:\Users\fabro\AppData\Local\Programs\Python\Python310\lib\site-packages\django\template\response.py", line 114, in render
    self.content = self.rendered_content
  File "C:\Users\fabro\AppData\Local\Programs\Python\Python310\lib\site-packages\django\template\response.py", line 92, in rendered_content
    return template.render(context, self._request)
  File "C:\Users\fabro\AppData\Local\Programs\Python\Python310\lib\site-packages\django\template\backends\django.py", line 62, in render
    return self.template.render(context)
  File "C:\Users\fabro\AppData\Local\Programs\Python\Python310\lib\site-packages\django\template\base.py", line 175, in render
    return self._render(context)
  File "C:\Users\fabro\AppData\Local\Programs\Python\Python310\lib\site-packages\django\template\base.py", line 167, in _render
    return self.nodelist.render(context)
  File "C:\Users\fabro\AppData\Local\Programs\Python\Python310\lib\site-packages\django\template\base.py", line 1005, in render
    return SafeString("".join([node.render_annotated(context) for node in self]))
  File "C:\Users\fabro\AppData\Local\Programs\Python\Python310\lib\site-packages\django\template\base.py", line 1005, in <listcomp>
    return SafeString("".join([node.render_annotated(context) for node in self]))
  File "C:\Users\fabro\AppData\Local\Programs\Python\Python310\lib\site-packages\django\template\base.py", line 966, in render_annotated
    return self.render(context)
  File "C:\Users\fabro\AppData\Local\Programs\Python\Python310\lib\site-packages\django\template\loader_tags.py", line 157, in render
    return compiled_parent._render(context)
  File "C:\Users\fabro\AppData\Local\Programs\Python\Python310\lib\site-packages\django\template\base.py", line 167, in _render
    return self.nodelist.render(context)
  File "C:\Users\fabro\AppData\Local\Programs\Python\Python310\lib\site-packages\django\template\base.py", line 1005, in render
    return SafeString("".join([node.render_annotated(context) for node in self]))
  File "C:\Users\fabro\AppData\Local\Programs\Python\Python310\lib\site-packages\django\template\base.py", line 1005, in <listcomp>
    return SafeString("".join([node.render_annotated(context) for node in self]))
  File "C:\Users\fabro\AppData\Local\Programs\Python\Python310\lib\site-packages\django\template\base.py", line 966, in render_annotated
    return self.render(context)
  File "C:\Users\fabro\AppData\Local\Programs\Python\Python310\lib\site-packages\django\template\loader_tags.py", line 208, in render
    return template.render(context)
  File "C:\Users\fabro\AppData\Local\Programs\Python\Python310\lib\site-packages\django\template\base.py", line 177, in render
    return self._render(context)
  File "C:\Users\fabro\AppData\Local\Programs\Python\Python310\lib\site-packages\django\template\base.py", line 167, in _render
    return self.nodelist.render(context)
  File "C:\Users\fabro\AppData\Local\Programs\Python\Python310\lib\site-packages\django\template\base.py", line 1005, in render
    return SafeString("".join([node.render_annotated(context) for node in self]))
  File "C:\Users\fabro\AppData\Local\Programs\Python\Python310\lib\site-packages\django\template\base.py", line 1005, in <listcomp>
    return SafeString("".join([node.render_annotated(context) for node in self]))
  File "C:\Users\fabro\AppData\Local\Programs\Python\Python310\lib\site-packages\django\template\base.py", line 966, in render_annotated
    return self.render(context)
  File "C:\Users\fabro\AppData\Local\Programs\Python\Python310\lib\site-packages\django\template\defaulttags.py", line 472, in render
    url = reverse(view_name, args=args, kwargs=kwargs, current_app=current_app)
  File "C:\Users\fabro\AppData\Local\Programs\Python\Python310\lib\site-packages\django\urls\base.py", line 88, in reverse
    return resolver._reverse_with_prefix(view, prefix, *args, **kwargs)
  File "C:\Users\fabro\AppData\Local\Programs\Python\Python310\lib\site-packages\django\urls\resolvers.py", line 828, in _reverse_with_prefix
    raise NoReverseMatch(msg)
django.urls.exceptions.NoReverseMatch: Reverse for 'logout' not found. 'logout' is not a valid view function or pattern name.
2022-11-12 15:30:44,907 Internal Server Error: /
Traceback (most recent call last):
  File "C:\Users\fabro\AppData\Local\Programs\Python\Python310\lib\site-packages\django\core\handlers\exception.py", line 55, in inner
    response = get_response(request)
  File "C:\Users\fabro\AppData\Local\Programs\Python\Python310\lib\site-packages\django\core\handlers\base.py", line 220, in _get_response
    response = response.render()
  File "C:\Users\fabro\AppData\Local\Programs\Python\Python310\lib\site-packages\django\template\response.py", line 114, in render
    self.content = self.rendered_content
  File "C:\Users\fabro\AppData\Local\Programs\Python\Python310\lib\site-packages\django\template\response.py", line 92, in rendered_content
    return template.render(context, self._request)
  File "C:\Users\fabro\AppData\Local\Programs\Python\Python310\lib\site-packages\django\template\backends\django.py", line 62, in render
    return self.template.render(context)
  File "C:\Users\fabro\AppData\Local\Programs\Python\Python310\lib\site-packages\django\template\base.py", line 175, in render
    return self._render(context)
  File "C:\Users\fabro\AppData\Local\Programs\Python\Python310\lib\site-packages\django\template\base.py", line 167, in _render
    return self.nodelist.render(context)
  File "C:\Users\fabro\AppData\Local\Programs\Python\Python310\lib\site-packages\django\template\base.py", line 1005, in render
    return SafeString("".join([node.render_annotated(context) for node in self]))
  File "C:\Users\fabro\AppData\Local\Programs\Python\Python310\lib\site-packages\django\template\base.py", line 1005, in <listcomp>
    return SafeString("".join([node.render_annotated(context) for node in self]))
  File "C:\Users\fabro\AppData\Local\Programs\Python\Python310\lib\site-packages\django\template\base.py", line 966, in render_annotated
    return self.render(context)
  File "C:\Users\fabro\AppData\Local\Programs\Python\Python310\lib\site-packages\django\template\loader_tags.py", line 157, in render
    return compiled_parent._render(context)
  File "C:\Users\fabro\AppData\Local\Programs\Python\Python310\lib\site-packages\django\template\base.py", line 167, in _render
    return self.nodelist.render(context)
  File "C:\Users\fabro\AppData\Local\Programs\Python\Python310\lib\site-packages\django\template\base.py", line 1005, in render
    return SafeString("".join([node.render_annotated(context) for node in self]))
  File "C:\Users\fabro\AppData\Local\Programs\Python\Python310\lib\site-packages\django\template\base.py", line 1005, in <listcomp>
    return SafeString("".join([node.render_annotated(context) for node in self]))
  File "C:\Users\fabro\AppData\Local\Programs\Python\Python310\lib\site-packages\django\template\base.py", line 966, in render_annotated
    return self.render(context)
  File "C:\Users\fabro\AppData\Local\Programs\Python\Python310\lib\site-packages\django\template\loader_tags.py", line 208, in render
    return template.render(context)
  File "C:\Users\fabro\AppData\Local\Programs\Python\Python310\lib\site-packages\django\template\base.py", line 177, in render
    return self._render(context)
  File "C:\Users\fabro\AppData\Local\Programs\Python\Python310\lib\site-packages\django\template\base.py", line 167, in _render
    return self.nodelist.render(context)
  File "C:\Users\fabro\AppData\Local\Programs\Python\Python310\lib\site-packages\django\template\base.py", line 1005, in render
    return SafeString("".join([node.render_annotated(context) for node in self]))
  File "C:\Users\fabro\AppData\Local\Programs\Python\Python310\lib\site-packages\django\template\base.py", line 1005, in <listcomp>
    return SafeString("".join([node.render_annotated(context) for node in self]))
  File "C:\Users\fabro\AppData\Local\Programs\Python\Python310\lib\site-packages\django\template\base.py", line 966, in render_annotated
    return self.render(context)
  File "C:\Users\fabro\AppData\Local\Programs\Python\Python310\lib\site-packages\django\template\defaulttags.py", line 472, in render
    url = reverse(view_name, args=args, kwargs=kwargs, current_app=current_app)
  File "C:\Users\fabro\AppData\Local\Programs\Python\Python310\lib\site-packages\django\urls\base.py", line 88, in reverse
    return resolver._reverse_with_prefix(view, prefix, *args, **kwargs)
  File "C:\Users\fabro\AppData\Local\Programs\Python\Python310\lib\site-packages\django\urls\resolvers.py", line 828, in _reverse_with_prefix
    raise NoReverseMatch(msg)
django.urls.exceptions.NoReverseMatch: Reverse for 'logout' not found. 'logout' is not a valid view function or pattern name.
2022-11-12 15:33:59,682 C:\PythonRemoteCZ7\Event_App\EventApp\urls.py changed, reloading.
2022-11-12 15:34:31,070 C:\PythonRemoteCZ7\Event_App\user\views.py changed, reloading.
2022-11-12 15:34:59,130 C:\PythonRemoteCZ7\Event_App\user\views.py changed, reloading.
2022-11-12 15:35:35,597 C:\PythonRemoteCZ7\Event_App\user\views.py changed, reloading.
2022-11-12 15:36:29,115 C:\PythonRemoteCZ7\Event_App\user\views.py changed, reloading.
2022-11-12 15:46:49,209 Internal Server Error: /one_event/4
Traceback (most recent call last):
  File "C:\Users\fabro\AppData\Local\Programs\Python\Python310\lib\site-packages\django\db\models\fields\__init__.py", line 2018, in get_prep_value
    return int(value)
TypeError: int() argument must be a string, a bytes-like object or a real number, not 'SimpleLazyObject'

The above exception was the direct cause of the following exception:

Traceback (most recent call last):
  File "C:\Users\fabro\AppData\Local\Programs\Python\Python310\lib\site-packages\django\core\handlers\exception.py", line 55, in inner
    response = get_response(request)
  File "C:\Users\fabro\AppData\Local\Programs\Python\Python310\lib\site-packages\django\core\handlers\base.py", line 197, in _get_response
    response = wrapped_callback(request, *callback_args, **callback_kwargs)
  File "C:\PythonRemoteCZ7\Event_App\base\views.py", line 34, in event_detail
    latest_response = EventResponse.objects.filter(
  File "C:\Users\fabro\AppData\Local\Programs\Python\Python310\lib\site-packages\django\db\models\manager.py", line 85, in manager_method
    return getattr(self.get_queryset(), name)(*args, **kwargs)
  File "C:\Users\fabro\AppData\Local\Programs\Python\Python310\lib\site-packages\django\db\models\query.py", line 1420, in filter
    return self._filter_or_exclude(False, args, kwargs)
  File "C:\Users\fabro\AppData\Local\Programs\Python\Python310\lib\site-packages\django\db\models\query.py", line 1438, in _filter_or_exclude
    clone._filter_or_exclude_inplace(negate, args, kwargs)
  File "C:\Users\fabro\AppData\Local\Programs\Python\Python310\lib\site-packages\django\db\models\query.py", line 1445, in _filter_or_exclude_inplace
    self._query.add_q(Q(*args, **kwargs))
  File "C:\Users\fabro\AppData\Local\Programs\Python\Python310\lib\site-packages\django\db\models\sql\query.py", line 1532, in add_q
    clause, _ = self._add_q(q_object, self.used_aliases)
  File "C:\Users\fabro\AppData\Local\Programs\Python\Python310\lib\site-packages\django\db\models\sql\query.py", line 1562, in _add_q
    child_clause, needed_inner = self.build_filter(
  File "C:\Users\fabro\AppData\Local\Programs\Python\Python310\lib\site-packages\django\db\models\sql\query.py", line 1478, in build_filter
    condition = self.build_lookup(lookups, col, value)
  File "C:\Users\fabro\AppData\Local\Programs\Python\Python310\lib\site-packages\django\db\models\sql\query.py", line 1303, in build_lookup
    lookup = lookup_class(lhs, rhs)
  File "C:\Users\fabro\AppData\Local\Programs\Python\Python310\lib\site-packages\django\db\models\lookups.py", line 27, in __init__
    self.rhs = self.get_prep_lookup()
  File "C:\Users\fabro\AppData\Local\Programs\Python\Python310\lib\site-packages\django\db\models\fields\related_lookups.py", line 166, in get_prep_lookup
    self.rhs = target_field.get_prep_value(self.rhs)
  File "C:\Users\fabro\AppData\Local\Programs\Python\Python310\lib\site-packages\django\db\models\fields\__init__.py", line 2020, in get_prep_value
    raise e.__class__(
TypeError: Field 'id' expected a number but got <SimpleLazyObject: <django.contrib.auth.models.AnonymousUser object at 0x0000021AEF598280>>.
2022-11-12 15:47:19,305 Internal Server Error: /one_event/6
Traceback (most recent call last):
  File "C:\Users\fabro\AppData\Local\Programs\Python\Python310\lib\site-packages\django\db\models\fields\__init__.py", line 2018, in get_prep_value
    return int(value)
TypeError: int() argument must be a string, a bytes-like object or a real number, not 'SimpleLazyObject'

The above exception was the direct cause of the following exception:

Traceback (most recent call last):
  File "C:\Users\fabro\AppData\Local\Programs\Python\Python310\lib\site-packages\django\core\handlers\exception.py", line 55, in inner
    response = get_response(request)
  File "C:\Users\fabro\AppData\Local\Programs\Python\Python310\lib\site-packages\django\core\handlers\base.py", line 197, in _get_response
    response = wrapped_callback(request, *callback_args, **callback_kwargs)
  File "C:\PythonRemoteCZ7\Event_App\base\views.py", line 34, in event_detail
    latest_response = EventResponse.objects.filter(
  File "C:\Users\fabro\AppData\Local\Programs\Python\Python310\lib\site-packages\django\db\models\manager.py", line 85, in manager_method
    return getattr(self.get_queryset(), name)(*args, **kwargs)
  File "C:\Users\fabro\AppData\Local\Programs\Python\Python310\lib\site-packages\django\db\models\query.py", line 1420, in filter
    return self._filter_or_exclude(False, args, kwargs)
  File "C:\Users\fabro\AppData\Local\Programs\Python\Python310\lib\site-packages\django\db\models\query.py", line 1438, in _filter_or_exclude
    clone._filter_or_exclude_inplace(negate, args, kwargs)
  File "C:\Users\fabro\AppData\Local\Programs\Python\Python310\lib\site-packages\django\db\models\query.py", line 1445, in _filter_or_exclude_inplace
    self._query.add_q(Q(*args, **kwargs))
  File "C:\Users\fabro\AppData\Local\Programs\Python\Python310\lib\site-packages\django\db\models\sql\query.py", line 1532, in add_q
    clause, _ = self._add_q(q_object, self.used_aliases)
  File "C:\Users\fabro\AppData\Local\Programs\Python\Python310\lib\site-packages\django\db\models\sql\query.py", line 1562, in _add_q
    child_clause, needed_inner = self.build_filter(
  File "C:\Users\fabro\AppData\Local\Programs\Python\Python310\lib\site-packages\django\db\models\sql\query.py", line 1478, in build_filter
    condition = self.build_lookup(lookups, col, value)
  File "C:\Users\fabro\AppData\Local\Programs\Python\Python310\lib\site-packages\django\db\models\sql\query.py", line 1303, in build_lookup
    lookup = lookup_class(lhs, rhs)
  File "C:\Users\fabro\AppData\Local\Programs\Python\Python310\lib\site-packages\django\db\models\lookups.py", line 27, in __init__
    self.rhs = self.get_prep_lookup()
  File "C:\Users\fabro\AppData\Local\Programs\Python\Python310\lib\site-packages\django\db\models\fields\related_lookups.py", line 166, in get_prep_lookup
    self.rhs = target_field.get_prep_value(self.rhs)
  File "C:\Users\fabro\AppData\Local\Programs\Python\Python310\lib\site-packages\django\db\models\fields\__init__.py", line 2020, in get_prep_value
    raise e.__class__(
TypeError: Field 'id' expected a number but got <SimpleLazyObject: <django.contrib.auth.models.AnonymousUser object at 0x0000021AEF89ADD0>>.
2022-11-12 15:47:55,055 Internal Server Error: /one_event/7
Traceback (most recent call last):
  File "C:\Users\fabro\AppData\Local\Programs\Python\Python310\lib\site-packages\django\db\models\fields\__init__.py", line 2018, in get_prep_value
    return int(value)
TypeError: int() argument must be a string, a bytes-like object or a real number, not 'SimpleLazyObject'

The above exception was the direct cause of the following exception:

Traceback (most recent call last):
  File "C:\Users\fabro\AppData\Local\Programs\Python\Python310\lib\site-packages\django\core\handlers\exception.py", line 55, in inner
    response = get_response(request)
  File "C:\Users\fabro\AppData\Local\Programs\Python\Python310\lib\site-packages\django\core\handlers\base.py", line 197, in _get_response
    response = wrapped_callback(request, *callback_args, **callback_kwargs)
  File "C:\PythonRemoteCZ7\Event_App\base\views.py", line 34, in event_detail
    latest_response = EventResponse.objects.filter(
  File "C:\Users\fabro\AppData\Local\Programs\Python\Python310\lib\site-packages\django\db\models\manager.py", line 85, in manager_method
    return getattr(self.get_queryset(), name)(*args, **kwargs)
  File "C:\Users\fabro\AppData\Local\Programs\Python\Python310\lib\site-packages\django\db\models\query.py", line 1420, in filter
    return self._filter_or_exclude(False, args, kwargs)
  File "C:\Users\fabro\AppData\Local\Programs\Python\Python310\lib\site-packages\django\db\models\query.py", line 1438, in _filter_or_exclude
    clone._filter_or_exclude_inplace(negate, args, kwargs)
  File "C:\Users\fabro\AppData\Local\Programs\Python\Python310\lib\site-packages\django\db\models\query.py", line 1445, in _filter_or_exclude_inplace
    self._query.add_q(Q(*args, **kwargs))
  File "C:\Users\fabro\AppData\Local\Programs\Python\Python310\lib\site-packages\django\db\models\sql\query.py", line 1532, in add_q
    clause, _ = self._add_q(q_object, self.used_aliases)
  File "C:\Users\fabro\AppData\Local\Programs\Python\Python310\lib\site-packages\django\db\models\sql\query.py", line 1562, in _add_q
    child_clause, needed_inner = self.build_filter(
  File "C:\Users\fabro\AppData\Local\Programs\Python\Python310\lib\site-packages\django\db\models\sql\query.py", line 1478, in build_filter
    condition = self.build_lookup(lookups, col, value)
  File "C:\Users\fabro\AppData\Local\Programs\Python\Python310\lib\site-packages\django\db\models\sql\query.py", line 1303, in build_lookup
    lookup = lookup_class(lhs, rhs)
  File "C:\Users\fabro\AppData\Local\Programs\Python\Python310\lib\site-packages\django\db\models\lookups.py", line 27, in __init__
    self.rhs = self.get_prep_lookup()
  File "C:\Users\fabro\AppData\Local\Programs\Python\Python310\lib\site-packages\django\db\models\fields\related_lookups.py", line 166, in get_prep_lookup
    self.rhs = target_field.get_prep_value(self.rhs)
  File "C:\Users\fabro\AppData\Local\Programs\Python\Python310\lib\site-packages\django\db\models\fields\__init__.py", line 2020, in get_prep_value
    raise e.__class__(
TypeError: Field 'id' expected a number but got <SimpleLazyObject: <django.contrib.auth.models.AnonymousUser object at 0x0000021AEF541C00>>.
2022-11-12 15:51:23,601 Internal Server Error: /one_event/6
Traceback (most recent call last):
  File "C:\Users\fabro\AppData\Local\Programs\Python\Python310\lib\site-packages\django\db\models\fields\__init__.py", line 2018, in get_prep_value
    return int(value)
TypeError: int() argument must be a string, a bytes-like object or a real number, not 'SimpleLazyObject'

The above exception was the direct cause of the following exception:

Traceback (most recent call last):
  File "C:\Users\fabro\AppData\Local\Programs\Python\Python310\lib\site-packages\django\core\handlers\exception.py", line 55, in inner
    response = get_response(request)
  File "C:\Users\fabro\AppData\Local\Programs\Python\Python310\lib\site-packages\django\core\handlers\base.py", line 197, in _get_response
    response = wrapped_callback(request, *callback_args, **callback_kwargs)
  File "C:\PythonRemoteCZ7\Event_App\base\views.py", line 34, in event_detail
    latest_response = EventResponse.objects.filter(
  File "C:\Users\fabro\AppData\Local\Programs\Python\Python310\lib\site-packages\django\db\models\manager.py", line 85, in manager_method
    return getattr(self.get_queryset(), name)(*args, **kwargs)
  File "C:\Users\fabro\AppData\Local\Programs\Python\Python310\lib\site-packages\django\db\models\query.py", line 1420, in filter
    return self._filter_or_exclude(False, args, kwargs)
  File "C:\Users\fabro\AppData\Local\Programs\Python\Python310\lib\site-packages\django\db\models\query.py", line 1438, in _filter_or_exclude
    clone._filter_or_exclude_inplace(negate, args, kwargs)
  File "C:\Users\fabro\AppData\Local\Programs\Python\Python310\lib\site-packages\django\db\models\query.py", line 1445, in _filter_or_exclude_inplace
    self._query.add_q(Q(*args, **kwargs))
  File "C:\Users\fabro\AppData\Local\Programs\Python\Python310\lib\site-packages\django\db\models\sql\query.py", line 1532, in add_q
    clause, _ = self._add_q(q_object, self.used_aliases)
  File "C:\Users\fabro\AppData\Local\Programs\Python\Python310\lib\site-packages\django\db\models\sql\query.py", line 1562, in _add_q
    child_clause, needed_inner = self.build_filter(
  File "C:\Users\fabro\AppData\Local\Programs\Python\Python310\lib\site-packages\django\db\models\sql\query.py", line 1478, in build_filter
    condition = self.build_lookup(lookups, col, value)
  File "C:\Users\fabro\AppData\Local\Programs\Python\Python310\lib\site-packages\django\db\models\sql\query.py", line 1303, in build_lookup
    lookup = lookup_class(lhs, rhs)
  File "C:\Users\fabro\AppData\Local\Programs\Python\Python310\lib\site-packages\django\db\models\lookups.py", line 27, in __init__
    self.rhs = self.get_prep_lookup()
  File "C:\Users\fabro\AppData\Local\Programs\Python\Python310\lib\site-packages\django\db\models\fields\related_lookups.py", line 166, in get_prep_lookup
    self.rhs = target_field.get_prep_value(self.rhs)
  File "C:\Users\fabro\AppData\Local\Programs\Python\Python310\lib\site-packages\django\db\models\fields\__init__.py", line 2020, in get_prep_value
    raise e.__class__(
TypeError: Field 'id' expected a number but got <SimpleLazyObject: <django.contrib.auth.models.AnonymousUser object at 0x0000021AEF8988B0>>.
2022-11-12 16:05:19,134 C:\PythonRemoteCZ7\Event_App\EventApp\urls.py changed, reloading.
